Workbook

Sheet 新25年新历销售
A1: 2025年（新历）昆明统一生物蝴蝶兰销售数量统计
A2: 月份 | C2: 小街基地 | Y2: 斗南门市 | AD2: 两处平均单价（花） | AG2: 砚山基地 | AL2: 染色花 | AU2: 合计发货数量 | AV2: 合计发货金额 | AW2: 切花合计发货数量 | AX2: 切花合计发货金额
B3: 国内数量 | D3: 金额 | F3: 国外 | T3: 小街销售数量合计 | U3: 金额合计 | V3: 小街平均单价（花） | X3: 斗南销售数量 | Z3: 斗南销售金额 | AB3: 斗南平均单价 | AF3: 砚山销售数量 | AH3: 砚山销售金额 | AJ3: 砚山平均单价 | AL3: 染色花销售数量 | AO3: 染色花销售金额 | AR3: 染色花平均单价
B4: 小花 | C4: 大花 | D4: 小 | E4: 大 | F4: 小苗数量 | G4: 金额 | H4: 中苗数量 | I4: 金额 | J4: 大苗数量 | K4: 金额 | L4: 俄罗斯数量 | N4: 金额 | P4: 国外数量 | R4: 国外金额
L5: 小 | M5: 大 | N5: 小 | O5: 大 | P5: 小 | Q5: 大 | R5: 小 | S5: 大 | V5: 小 | W5: 大 | X5: 小 | Y5: 大 | Z5: 小 | AA5: 大 | AB5: 小 | AC5: 大 | AD5: 小花 | AE5: 大花 | AF5: 小 | AG5: 大 | AH5: 小 | AI5: 大 | AJ5: 小 | AK5: 大 | AL5: 2.8 | AM5: 3 | AN5: 3.5 | AO5: 2.8 | AP5: 3 | AQ5: 3.5 | AR5: 2.8 | AS5: 3 | AT5: 3.5
A6: 1月 | C6: 72387 | E6: 1427651 | J6: 40 | K6: 690 | M6: 4992 | O6: 115444 | Q6: 118764 | S6: 2655256 | T6: =C6+F6+H6+J6+M6+Q6+B6+L6+P6 -> 196183 | U6: =E6+G6+I6+K6+O6+S6+D6+N6+R6 -> 4199041 | V6: =(D6+N6+R6)/(B6+L6+P6) -> #DIV/0! | W6: =(E6+O6+S6)/(C6+M6+Q6) -> 21.404542 | Y6: 32831 | AA6: 555715 | AB6: =Z6/X6 -> #DIV/0! | AC6: =AA6/Y6 -> 16.926533 | AD6: =(D6+N6+R6+Z6)/(B6+L6+P6+X6) -> #DIV/0! | AE6: =(E6+O6+S6+AA6)/(C6+M6+Q6+Y6) -> 20.762471 | AJ6: =AH6/AF6 -> #DIV/0! | AK6: =AI6/AG6 -> #DIV/0! | AR6: =AO6/AL6 -> #DIV/0! | AS6: =AP6/AM6 -> #DIV/0! | AT6: =AQ6/AN6 -> #DIV/0! | AU6: =T6+X6+Y6+AF6+AG6+AL6+AM6+AN6 -> 229014 | AV6: =U6+Z6+AA6+AH6+AI6+AO6+AP6+AQ6 -> 4754756 | AW6: 820 | AX6: 10020
A7: 2月 | C7: 25399 | E7: =404913-8910 -> 396003 | M7: 88202 | O7: 2167000 | T7: =C7+F7+H7+J7+M7+Q7+B7+L7+P7 -> 113601 | U7: =E7+G7+I7+K7+O7+S7+D7+N7+R7 -> 2563003 | V7: =(D7+N7+R7)/(B7+L7+P7) -> #DIV/0! | W7: =(E7+O7+S7)/(C7+M7+Q7) -> 22.561448 | Y7: 14768 | AA7: 175156 | AB7: =Z7/X7 -> #DIV/0! | AC7: =AA7/Y7 -> 11.860509 | AD7: =(D7+N7+R7+Z7)/(B7+L7+P7+X7) -> #DIV/0! | AE7: =(E7+O7+S7+AA7)/(C7+M7+Q7+Y7) -> 21.330376 | AJ7: =AH7/AF7 -> #DIV/0! | AK7: =AI7/AG7 -> #DIV/0! | AR7: =AO7/AL7 -> #DIV/0! | AS7: =AP7/AM7 -> #DIV/0! | AT7: =AQ7/AN7 -> #DIV/0! | AU7: =T7+X7+Y7+AF7+AG7+AL7+AM7+AN7 -> 128369 | AV7: =U7+Z7+AA7+AH7+AI7+AO7+AP7+AQ7 -> 2738159 | AW7: 640 | AX7: 8910
A8: 3月 | C8: 13835 | E8: =201151-24095 -> 177056 | M8: 34560 | O8: 879760 | Q8: 1240 | S8: =58619-27560 -> 31059 | T8: =C8+F8+H8+J8+M8+Q8+B8+L8+P8 -> 49635 | U8: =E8+G8+I8+K8+O8+S8+D8+N8+R8 -> 1087875 | V8: =(D8+N8+R8)/(B8+L8+P8) -> #DIV/0! | W8: =(E8+O8+S8)/(C8+M8+Q8) -> 21.917498 | Y8: 11771 | AA8: =92904-507 -> 92397 | AB8: =Z8/X8 -> #DIV/0! | AC8: =AA8/Y8 -> 7.8495455 | AD8: =(D8+N8+R8+Z8)/(B8+L8+P8+X8) -> #DIV/0! | AE8: =(E8+O8+S8+AA8)/(C8+M8+Q8+Y8) -> 19.220793 | AJ8: =AH8/AF8 -> #DIV/0! | AK8: =AI8/AG8 -> #DIV/0! | AR8: =AO8/AL8 -> #DIV/0! | AS8: =AP8/AM8 -> #DIV/0! | AT8: =AQ8/AN8 -> #DIV/0! | AU8: =T8+X8+Y8+AF8+AG8+AL8+AM8+AN8 -> 61406 | AV8: =U8+Z8+AA8+AH8+AI8+AO8+AP8+AQ8 -> 1180272 | AW8: 4654 | AX8: 24602
A9: 4月 | C9: 24964 | E9: =426350-4500 -> 421850 | H9: 30000 | I9: =258900-3900 -> 255000 | Q9: 320 | S9: 8320 | T9: =C9+F9+H9+J9+M9+Q9+B9+L9+P9 -> 55284 | U9: =E9+G9+I9+K9+O9+S9+D9+N9+R9 -> 685170 | V9: =(D9+N9+R9)/(B9+L9+P9) -> #DIV/0! | W9: =(E9+O9+S9)/(C9+M9+Q9) -> 17.013526 | Y9: 6934 | AA9: =109224-368 -> 108856 | AB9: =Z9/X9 -> #DIV/0! | AC9: =AA9/Y9 -> 15.698875 | AD9: =(D9+N9+R9+Z9)/(B9+L9+P9+X9) -> #DIV/0! | AE9: =(E9+O9+S9+AA9)/(C9+M9+Q9+Y9) -> 16.730585 | AJ9: =AH9/AF9 -> #DIV/0! | AK9: =AI9/AG9 -> #DIV/0! | AU9: =T9+X9+Y9+AF9+AG9+AL9+AM9+AN9 -> 62218 | AV9: =U9+Z9+AA9+AH9+AI9+AO9+AP9+AQ9 -> 794026 | AW9: 406 | AX9: 4868
A10: 5月 | B10: 2462 | C10: 23352 | D10: 32251 | E10: 403004 | L10: 31200 | N10: 530400 | P10: 560 | Q10: 300 | R10: 13660 | S10: 7800 | T10: =C10+F10+H10+J10+M10+Q10+B10+L10+P10 -> 57874 | U10: =E10+G10+I10+K10+O10+S10+D10+N10+R10 -> 987115 | V10: =(D10+N10+R10)/(B10+L10+P10) -> 16.840366 | W10: =(E10+O10+S10)/(C10+M10+Q10) -> 17.368679 | X10: 1038 | Y10: 9151 | Z10: 13374 | AA10: 134558 | AB10: =Z10/X10 -> 12.884393 | AC10: =AA10/Y10 -> 14.704185 | AD10: =(D10+N10+R10+Z10)/(B10+L10+P10+X10) -> 16.723908 | AE10: =(E10+O10+S10+AA10)/(C10+M10+Q10+Y10) -> 16.62537 | AJ10: =AH10/AF10 -> #DIV/0! | AK10: =AI10/AG10 -> #DIV/0! | AR10: =AO10/AL10 -> #DIV/0! | AS10: =AP10/AM10 -> #DIV/0! | AT10: =AQ10/AN10 -> #DIV/0! | AU10: =T10+X10+Y10+AF10+AG10+AL10+AM10+AN10 -> 68063 | AV10: =U10+Z10+AA10+AH10+AI10+AO10+AP10+AQ10 -> 1135047 | AW10: 698 | AX10: 6510
A11: 5.26-6.10 | B11: 2459 | C11: 22260 | D11: 35308 | E11: 359040 | P11: 14384 | Q11: 11400 | R11: 244528 | S11: 297800 | T11: =C11+F11+H11+J11+M11+Q11+B11+L11+P11 -> 50503 | U11: =E11+G11+I11+K11+O11+S11+D11+N11+R11 -> 936676 | V11: =(D11+N11+R11)/(B11+L11+P11) -> 16.61438 | W11: =(E11+O11+S11)/(C11+M11+Q11) -> 19.513963 | X11: 999 | Y11: 5323 | Z11: 12186 | AA11: 63135 | AB11: =Z11/X11 -> 12.198198 | AC11: =AA11/Y11 -> 11.860793 | AD11: =(D11+N11+R11+Z11)/(B11+L11+P11+X11) -> 16.367111 | AE11: =(E11+O11+S11+AA11)/(C11+M11+Q11+Y11) -> 18.468948 | AJ11: =AH11/AF11 -> #DIV/0! | AK11: =AI11/AG11 -> #DIV/0! | AR11: =AO11/AL11 -> #DIV/0! | AS11: =AP11/AM11 -> #DIV/0! | AT11: =AQ11/AN11 -> #DIV/0! | AU11: =T11+X11+Y11+AF11+AG11+AL11+AM11+AN11 -> 56825 | AV11: =U11+Z11+AA11+AH11+AI11+AO11+AP11+AQ11 -> 1011997 | AW11: 1770 | AX11: 8475
T12: =C12+F12+H12+J12+M12+Q12+B12+L12+P12 -> 0 | U12: =E12+G12+I12+K12+O12+S12+D12+N12+R12 -> 0 | V12: =(D12+N12+R12)/(B12+L12+P12) -> #DIV/0! | W12: =(E12+O12+S12)/(C12+M12+Q12) -> #DIV/0! | AB12: =Z12/X12 -> #DIV/0! | AC12: =AA12/Y12 -> #DIV/0! | AD12: =(D12+N12+R12+Z12)/(B12+L12+P12+X12) -> #DIV/0! | AE12: =(E12+O12+S12+AA12)/(C12+M12+Q12+Y12) -> #DIV/0! | AJ12: =AH12/AF12 -> #DIV/0! | AK12: =AI12/AG12 -> #DIV/0! | AR12: =AO12/AL12 -> #DIV/0! | AS12: =AP12/AM12 -> #DIV/0! | AT12: =AQ12/AN12 -> #DIV/0! | AU12: =T12+X12+Y12+AF12+AG12+AL12+AM12+AN12 -> 0 | AV12: =U12+Z12+AA12+AH12+AI12+AO12+AP12+AQ12 -> 0
T13: =C13+F13+H13+J13+M13+Q13+B13+L13+P13 -> 0 | U13: =E13+G13+I13+K13+O13+S13+D13+N13+R13 -> 0 | V13: =(D13+N13+R13)/(B13+L13+P13) -> #DIV/0! | W13: =(E13+O13+S13)/(C13+M13+Q13) -> #DIV/0! | AB13: =Z13/X13 -> #DIV/0! | AC13: =AA13/Y13 -> #DIV/0! | AD13: =(D13+N13+R13+Z13)/(B13+L13+P13+X13) -> #DIV/0! | AE13: =(E13+O13+S13+AA13)/(C13+M13+Q13+Y13) -> #DIV/0! | AJ13: =AH13/AF13 -> #DIV/0! | AK13: =AI13/AG13 -> #DIV/0! | AR13: =AO13/AL13 -> #DIV/0! | AS13: =AP13/AM13 -> #DIV/0! | AT13: =AQ13/AN13 -> #DIV/0! | AU13: =T13+X13+Y13+AF13+AG13+AL13+AM13+AN13 -> 0 | AV13: =U13+Z13+AA13+AH13+AI13+AO13+AP13+AQ13 -> 0
T14: =C14+F14+H14+J14+M14+Q14+B14+L14+P14 -> 0 | U14: =E14+G14+I14+K14+O14+S14+D14+N14+R14 -> 0 | V14: =(D14+N14+R14)/(B14+L14+P14) -> #DIV/0! | W14: =(E14+O14+S14)/(C14+M14+Q14) -> #DIV/0! | AB14: =Z14/X14 -> #DIV/0! | AC14: =AA14/Y14 -> #DIV/0! | AD14: =(D14+N14+R14+Z14)/(B14+L14+P14+X14) -> #DIV/0! | AE14: =(E14+O14+S14+AA14)/(C14+M14+Q14+Y14) -> #DIV/0! | AJ14: =AH14/AF14 -> #DIV/0! | AK14: =AI14/AG14 -> #DIV/0! | AR14: =AO14/AL14 -> #DIV/0! | AS14: =AP14/AM14 -> #DIV/0! | AT14: =AQ14/AN14 -> #DIV/0! | AU14: =T14+X14+Y14+AF14+AG14+AL14+AM14+AN14 -> 0 | AV14: =U14+Z14+AA14+AH14+AI14+AO14+AP14+AQ14 -> 0
T15: =C15+F15+H15+J15+M15+Q15+B15+L15+P15 -> 0 | U15: =E15+G15+I15+K15+O15+S15+D15+N15+R15 -> 0 | V15: =(D15+N15+R15)/(B15+L15+P15) -> #DIV/0! | W15: =(E15+O15+S15)/(C15+M15+Q15) -> #DIV/0! | AB15: =Z15/X15 -> #DIV/0! | AC15: =AA15/Y15 -> #DIV/0! | AD15: =(D15+N15+R15+Z15)/(B15+L15+P15+X15) -> #DIV/0! | AE15: =(E15+O15+S15+AA15)/(C15+M15+Q15+Y15) -> #DIV/0! | AJ15: =AH15/AF15 -> #DIV/0! | AK15: =AI15/AG15 -> #DIV/0! | AR15: =AO15/AL15 -> #DIV/0! | AS15: =AP15/AM15 -> #DIV/0! | AT15: =AQ15/AN15 -> #DIV/0! | AU15: =T15+X15+Y15+AF15+AG15+AL15+AM15+AN15 -> 0 | AV15: =U15+Z15+AA15+AH15+AI15+AO15+AP15+AQ15 -> 0
T16: =C16+F16+H16+J16+M16+Q16+B16+L16+P16 -> 0 | U16: =E16+G16+I16+K16+O16+S16+D16+N16+R16 -> 0 | V16: =(D16+N16+R16)/(B16+L16+P16) -> #DIV/0! | W16: =(E16+O16+S16)/(C16+M16+Q16) -> #DIV/0! | AB16: =Z16/X16 -> #DIV/0! | AC16: =AA16/Y16 -> #DIV/0! | AD16: =(D16+N16+R16+Z16)/(B16+L16+P16+X16) -> #DIV/0! | AE16: =(E16+O16+S16+AA16)/(C16+M16+Q16+Y16) -> #DIV/0! | AJ16: =AH16/AF16 -> #DIV/0! | AK16: =AI16/AG16 -> #DIV/0! | AR16: =AO16/AL16 -> #DIV/0! | AS16: =AP16/AM16 -> #DIV/0! | AT16: =AQ16/AN16 -> #DIV/0! | AU16: =T16+X16+Y16+AF16+AG16+AL16+AM16+AN16 -> 0 | AV16: =U16+Z16+AA16+AH16+AI16+AO16+AP16+AQ16 -> 0
T17: =C17+F17+H17+J17+M17+Q17+B17+L17+P17 -> 0 | U17: =E17+G17+I17+K17+O17+S17+D17+N17+R17 -> 0 | V17: =(D17+N17+R17)/(B17+L17+P17) -> #DIV/0! | W17: =(E17+O17+S17)/(C17+M17+Q17) -> #DIV/0! | AB17: =Z17/X17 -> #DIV/0! | AC17: =AA17/Y17 -> #DIV/0! | AD17: =(D17+N17+R17+Z17)/(B17+L17+P17+X17) -> #DIV/0! | AE17: =(E17+O17+S17+AA17)/(C17+M17+Q17+Y17) -> #DIV/0! | AJ17: =AH17/AF17 -> #DIV/0! | AK17: =AI17/AG17 -> #DIV/0! | AR17: =AO17/AL17 -> #DIV/0! | AS17: =AP17/AM17 -> #DIV/0! | AT17: =AQ17/AN17 -> #DIV/0! | AU17: =T17+X17+Y17+AF17+AG17+AL17+AM17+AN17 -> 0 | AV17: =U17+Z17+AA17+AH17+AI17+AO17+AP17+AQ17 -> 0
A18: 合计 | B18: =SUM(B6:B17) -> 4921 | C18: =SUM(C6:C17) -> 182197 | D18: =SUM(D6:D17) -> 67559 | E18: =SUM(E6:E17) -> 3184604 | F18: =SUM(F6:F17) -> 0 | G18: =SUM(G6:G17) -> 0 | H18: =SUM(H6:H17) -> 30000 | I18: =SUM(I6:I17) -> 255000 | ... U18: =SUM(U6:U17) -> 10458880 | V18: =(D18+N18+R18)/(B18+L18+P18) -> 16.765828 | W18: =(E18+O18+S18)/(C18+M18+Q18) -> 21.130704 | X18: =SUM(X6:X17) -> 2037 | Y18: =SUM(Y6:Y17) -> 80778 | Z18: =SUM(Z6:Z17) -> 25560 | AA18: =SUM(AA6:AA17) -> 1129817 | AB18: =Z18/X18 -> 12.547865 | AC18: =AA18/Y18 -> 13.986692 | AD18: =(D18+N18+R18+Z18)/(B18+L18+P18+X18) -> 16.604026 | AE18: =(E18+O18+S18+AA18)/(C18+M18+Q18+Y18) -> 20.026781 | AF18: =SUM(AF6:AF17) -> 0 | AG18: =SUM(AG6:AG17) -> 0 | AH18: =SUM(AH6:AH17) -> 0 | AI18: =SUM(AI6:AI17) -> 0 | AJ18: =AH18/AF18 -> #DIV/0! | AK18: =AI18/AG18 -> #DIV/0! | AL18: =SUM(AL6:AL17) -> 0 | AM18: =SUM(AM6:AM17) -> 0 | AN18: =SUM(AN6:AN17) -> 0 | AO18: =SUM(AO6:AO17) -> 0 | AP18: =SUM(AP6:AP17) -> 0 | AQ18: =SUM(AQ6:AQ17) -> 0 | AR18: =SUM(AR6:AR17) -> #DIV/0! | AS18: =SUM(AS6:AS17) -> #DIV/0! | AT18: =SUM(AT6:AT17) -> #DIV/0! | AU18: =T18+X18+Y18+AF18+AG18+AL18+AM18+AN18 -> 605895 | AV18: =U18+Z18+AA18+AH18+AI18+AO18+AP18+AQ18 -> 11614257 | AW18: =SUM(AW6:AW17) -> 8988 | AX18: =SUM(AX6:AX17) -> 63385
X26: =T18+X18+Y18+AF18+AG18+AL18+AM18+AN18 -> 605895

Sheet 新25年农历销售
A1: 2025年（农历）昆明统一生物蝴蝶兰销售数量统计
A2: 月份 | C2: 小街基地 | Y2: 斗南门市 | AD2: 两处平均单价（花） | AG2: 砚山基地 | AL2: 染色花 | AU2: 合计发货数量 | AV2: 合计发货金额 | AW2: 切花合计发货数量 | AX2: 切花合计发货金额
B3: 国内数量 | D3: 金额 | F3: 国外 | T3: 小街销售数量合计 | U3: 金额合计 | V3: 小街平均单价（花） | X3: 斗南销售数量 | Z3: 斗南销售金额 | AB3: 斗南平均单价 | AF3: 砚山销售数量 | AH3: 砚山销售金额 | AJ3: 砚山平均单价 | AL3: 染色花销售数量 | AO3: 染色花销售金额 | AR3: 染色花平均单价
B4: 小花 | C4: 大花 | D4: 小 | E4: 大 | F4: 小苗数量 | G4: 金额 | H4: 中苗数量 | I4: 金额 | J4: 大苗数量 | K4: 金额 | L4: 俄罗斯数量 | N4: 金额 | P4: 国外数量 | R4: 国外金额
L5: 小 | M5: 大 | N5: 小 | O5: 大 | P5: 小 | Q5: 大 | R5: 小 | S5: 大 | V5: 小 | W5: 大 | X5: 小 | Y5: 大 | Z5: 小 | AA5: 大 | AB5: 小 | AC5: 大 | AD5: 小花 | AE5: 大花 | AF5: 小 | AG5: 大 | AH5: 小 | AI5: 大 | AJ5: 小 | AK5: 大 | AL5: 2.8 | AM5: 3 | AN5: 3.5 | AO5: 2.8 | AP5: 3 | AQ5: 3.5 | AR5: 2.8 | AS5: 3 | AT5: 3.5
A6: 1.29-2.25 | C6: 25134 | E6: =400906-8910 -> 391996 | M6: 71402 | O6: 1831000 | T6: =C6+F6+H6+J6+M6+Q6+B6+L6+P6 -> 96536 | U6: =E6+G6+I6+K6+O6+S6+D6+N6+R6 -> 2222996 | V6: =(D6+N6+R6)/(B6+L6+P6) -> #DIV/0! | W6: =(E6+O6+S6)/(C6+M6+Q6) -> 23.027637 | Y6: 14739 | AA6: 180866 | AB6: =Z6/X6 -> #DIV/0! | AC6: =AA6/Y6 -> 12.271253 | AD6: =(D6+N6+R6+Z6)/(B6+L6+P6+X6) -> #DIV/0! | AE6: =(E6+O6+S6+AA6)/(C6+M6+Q6+Y6) -> 21.602894 | AJ6: =AH6/AF6 -> #DIV/0! | AK6: =AI6/AG6 -> #DIV/0! | AU6: =T6+X6+Y6+AF6+AG6+AL6+AM6+AN6 -> 111275 | AV6: =U6+Z6+AA6+AH6+AI6+AO6+AP6+AQ6 -> 2403862 | AW6: 820 | AX6: 10020
A7: 3月 | C7: 13835 | E7: =201151-24095 -> 177056 | M7: 34560 | O7: 879760 | Q7: 1240 | S7: =58619-27560 -> 31059 | T7: =C7+F7+H7+J7+M7+Q7+B7+L7+P7 -> 49635 | U7: =E7+G7+I7+K7+O7+S7+D7+N7+R7 -> 1087875 | V7: =(D7+N7+R7)/(B7+L7+P7) -> #DIV/0! | W7: =(E7+O7+S7)/(C7+M7+Q7) -> 21.917498 | Y7: 11771 | AA7: =92904-507 -> 92397 | AB7: =Z7/X7 -> #DIV/0! | AC7: =AA7/Y7 -> 7.8495455 | AD7: =(D7+N7+R7+Z7)/(B7+L7+P7+X7) -> #DIV/0! | AE7: =(E7+O7+S7+AA7)/(C7+M7+Q7+Y7) -> 19.220793 | AJ7: =AH7/AF7 -> #DIV/0! | AK7: =AI7/AG7 -> #DIV/0! | AR7: =AO7/AL7 -> #DIV/0! | AS7: =AP7/AM7 -> #DIV/0! | AT7: =AQ7/AN7 -> #DIV/0! | AU7: =T7+X7+Y7+AF7+AG7+AL7+AM7+AN7 -> 61406 | AV7: =U7+Z7+AA7+AH7+AI7+AO7+AP7+AQ7 -> 1180272 | AW7: 4654 | AX7: 24602
A8: 4月 | C8: 24964 | E8: =426350-4500 -> 421850 | H8: 30000 | I8: =258900-3900 -> 255000 | Q8: 320 | S8: 8320 | T8: =C8+F8+H8+J8+M8+Q8+B8+L8+P8 -> 55284 | U8: =E8+G8+I8+K8+O8+S8+D8+N8+R8 -> 685170 | V8: =(D8+N8+R8)/(B8+L8+P8) -> #DIV/0! | W8: =(E8+O8+S8)/(C8+M8+Q8) -> 17.013526 | Y8: 6934 | AA8: =109224-368 -> 108856 | AB8: =Z8/X8 -> #DIV/0! | AC8: =AA8/Y8 -> 15.698875 | AD8: =(D8+N8+R8+Z8)/(B8+L8+P8+X8) -> #DIV/0! | AE8: =(E8+O8+S8+AA8)/(C8+M8+Q8+Y8) -> 16.730585 | AJ8: =AH8/AF8 -> #DIV/0! | AK8: =AI8/AG8 -> #DIV/0! | AU8: =T8+X8+Y8+AF8+AG8+AL8+AM8+AN8 -> 62218 | AV8: =U8+Z8+AA8+AH8+AI8+AO8+AP8+AQ8 -> 794026 | AW8: 406 | AX8: 4868
A9: 5月 | B9: 2462 | C9: 23352 | D9: 32251 | E9: 403004 | L9: 31200 | N9: 530400 | P9: 560 | Q9: 300 | R9: 13660 | S9: 7800 | T9: =C9+F9+H9+J9+M9+Q9+B9+L9+P9 -> 57874 | U9: =E9+G9+I9+K9+O9+S9+D9+N9+R9 -> 987115 | V9: =(D9+N9+R9)/(B9+L9+P9) -> 16.840366 | W9: =(E9+O9+S9)/(C9+M9+Q9) -> 17.368679 | X9: 1038 | Y9: 9151 | Z9: 13374 | AA9: 134558 | AB9: =Z9/X9 -> 12.884393 | AC9: =AA9/Y9 -> 14.704185 | AD9: =(D9+N9+R9+Z9)/(B9+L9+P9+X9) -> 16.723908 | AE9: =(E9+O9+S9+AA9)/(C9+M9+Q9+Y9) -> 16.62537 | AJ9: =AH9/AF9 -> #DIV/0! | AK9: =AI9/AG9 -> #DIV/0! | AR9: =AO9/AL9 -> #DIV/0! | AS9: =AP9/AM9 -> #DIV/0! | AT9: =AQ9/AN9 -> #DIV/0! | AU9: =T9+X9+Y9+AF9+AG9+AL9+AM9+AN9 -> 68063 | AV9: =U9+Z9+AA9+AH9+AI9+AO9+AP9+AQ9 -> 1135047 | AW9: 698 | AX9: 6510
A10: 5.26-6.10 | B10: 2459 | C10: 22260 | D10: 35308 | E10: 359040 | P10: 14384 | Q10: 11400 | R10: 244528 | S10: 297800 | T10: =C10+F10+H10+J10+M10+Q10+B10+L10+P10 -> 50503 | U10: =E10+G10+I10+K10+O10+S10+D10+N10+R10 -> 936676 | V10: =(D10+N10+R10)/(B10+L10+P10) -> 16.61438 | W10: =(E10+O10+S10)/(C10+M10+Q10) -> 19.513963 | X10: 999 | Y10: 5323 | Z10: 12186 | AA10: 63135 | AB10: =Z10/X10 -> 12.198198 | AC10: =AA10/Y10 -> 11.860793 | AD10: =(D10+N10+R10+Z10)/(B10+L10+P10+X10) -> 16.367111 | AE10: =(E10+O10+S10+AA10)/(C10+M10+Q10+Y10) -> 18.468948 | AJ10: =AH10/AF10 -> #DIV/0! | AK10: =AI10/AG10 -> #DIV/0! | AR10: =AO10/AL10 -> #DIV/0! | AS10: =AP10/AM10 -> #DIV/0! | AT10: =AQ10/AN10 -> #DIV/0! | AU10: =T10+X10+Y10+AF10+AG10+AL10+AM10+AN10 -> 56825 | AV10: =U10+Z10+AA10+AH10+AI10+AO10+AP10+AQ10 -> 1011997 | AW10: 1770 | AX10: 8475
T11: =C11+F11+H11+J11+M11+Q11+B11+L11+P11 -> 0 | U11: =E11+G11+I11+K11+O11+S11+D11+N11+R11 -> 0 | V11: =(D11+N11+R11)/(B11+L11+P11) -> #DIV/0! | W11: =(E11+O11+S11)/(C11+M11+Q11) -> #DIV/0! | AB11: =Z11/X11 -> #DIV/0! | AC11: =AA11/Y11 -> #DIV/0! | AD11: =(D11+N11+R11+Z11)/(B11+L11+P11+X11) -> #DIV/0! | AE11: =(E11+O11+S11+AA11)/(C11+M11+Q11+Y11) -> #DIV/0! | AJ11: =AH11/AF11 -> #DIV/0! | AK11: =AI11/AG11 -> #DIV/0! | AU11: =T11+X11+Y11+AF11+AG11+AL11+AM11+AN11 -> 0 | AV11: =U11+Z11+AA11+AH11+AI11+AO11+AP11+AQ11 -> 0
T12: =C12+F12+H12+J12+M12+Q12+B12+L12+P12 -> 0 | U12: =E12+G12+I12+K12+O12+S12+D12+N12+R12 -> 0 | V12: =(D12+N12+R12)/(B12+L12+P12) -> #DIV/0! | W12: =(E12+O12+S12)/(C12+M12+Q12) -> #DIV/0! | AB12: =Z12/X12 -> #DIV/0! | AC12: =AA12/Y12 -> #DIV/0! | AD12: =(D12+N12+R12+Z12)/(B12+L12+P12+X12) -> #DIV/0! | AE12: =(E12+O12+S12+AA12)/(C12+M12+Q12+Y12) -> #DIV/0! | AJ12: =AH12/AF12 -> #DIV/0! | AK12: =AI12/AG12 -> #DIV/0! | AU12: =T12+X12+Y12+AF12+AG12+AL12+AM12+AN12 -> 0 | AV12: =U12+Z12+AA12+AH12+AI12+AO12+AP12+AQ12 -> 0
T13: =C13+F13+H13+J13+M13+Q13+B13+L13+P13 -> 0 | U13: =E13+G13+I13+K13+O13+S13+D13+N13+R13 -> 0 | V13: =(D13+N13+R13)/(B13+L13+P13) -> #DIV/0! | W13: =(E13+O13+S13)/(C13+M13+Q13) -> #DIV/0! | AB13: =Z13/X13 -> #DIV/0! | AC13: =AA13/Y13 -> #DIV/0! | AD13: =(D13+N13+R13+Z13)/(B13+L13+P13+X13) -> #DIV/0! | AE13: =(E13+O13+S13+AA13)/(C13+M13+Q13+Y13) -> #DIV/0! | AJ13: =AH13/AF13 -> #DIV/0! | AK13: =AI13/AG13 -> #DIV/0! | AU13: =T13+X13+Y13+AF13+AG13+AL13+AM13+AN13 -> 0 | AV13: =U13+Z13+AA13+AH13+AI13+AO13+AP13+AQ13 -> 0
T14: =C14+F14+H14+J14+M14+Q14+B14+L14+P14 -> 0 | U14: =E14+G14+I14+K14+O14+S14+D14+N14+R14 -> 0 | V14: =(D14+N14+R14)/(B14+L14+P14) -> #DIV/0! | W14: =(E14+O14+S14)/(C14+M14+Q14) -> #DIV/0! | AB14: =Z14/X14 -> #DIV/0! | AC14: =AA14/Y14 -> #DIV/0! | AD14: =(D14+N14+R14+Z14)/(B14+L14+P14+X14) -> #DIV/0! | AE14: =(E14+O14+S14+AA14)/(C14+M14+Q14+Y14) -> #DIV/0! | AJ14: =AH14/AF14 -> #DIV/0! | AK14: =AI14/AG14 -> #DIV/0! | AU14: =T14+X14+Y14+AF14+AG14+AL14+AM14+AN14 -> 0 | AV14: =U14+Z14+AA14+AH14+AI14+AO14+AP14+AQ14 -> 0
T15: =C15+F15+H15+J15+M15+Q15+B15+L15+P15 -> 0 | U15: =E15+G15+I15+K15+O15+S15+D15+N15+R15 -> 0 | V15: =(D15+N15+R15)/(B15+L15+P15) -> #DIV/0! | W15: =(E15+O15+S15)/(C15+M15+Q15) -> #DIV/0! | AB15: =Z15/X15 -> #DIV/0! | AC15: =AA15/Y15 -> #DIV/0! | AD15: =(D15+N15+R15+Z15)/(B15+L15+P15+X15) -> #DIV/0! | AE15: =(E15+O15+S15+AA15)/(C15+M15+Q15+Y15) -> #DIV/0! | AJ15: =AH15/AF15 -> #DIV/0! | AK15: =AI15/AG15 -> #DIV/0! | AU15: =T15+X15+Y15+AF15+AG15+AL15+AM15+AN15 -> 0 | AV15: =U15+Z15+AA15+AH15+AI15+AO15+AP15+AQ15 -> 0
T16: =C16+F16+H16+J16+M16+Q16+B16+L16+P16 -> 0 | U16: =E16+G16+I16+K16+O16+S16+D16+N16+R16 -> 0 | V16: =(D16+N16+R16)/(B16+L16+P16) -> #DIV/0! | W16: =(E16+O16+S16)/(C16+M16+Q16) -> #DIV/0! | AB16: =Z16/X16 -> #DIV/0! | AC16: =AA16/Y16 -> #DIV/0! | AD16: =(D16+N16+R16+Z16)/(B16+L16+P16+X16) -> #DIV/0! | AE16: =(E16+O16+S16+AA16)/(C16+M16+Q16+Y16) -> #DIV/0! | AJ16: =AH16/AF16 -> #DIV/0! | AK16: =AI16/AG16 -> #DIV/0! | AU16: =T16+X16+Y16+AF16+AG16+AL16+AM16+AN16 -> 0 | AV16: =U16+Z16+AA16+AH16+AI16+AO16+AP16+AQ16 -> 0
T17: =C17+F17+H17+J17+M17+Q17+B17+L17+P17 -> 0 | U17: =E17+G17+I17+K17+O17+S17+D17+N17+R17 -> 0 | V17: =(D17+N17+R17)/(B17+L17+P17) -> #DIV/0! | W17: =(E17+O17+S17)/(C17+M17+Q17) -> #DIV/0! | AB17: =Z17/X17 -> #DIV/0! | AC17: =AA17/Y17 -> #DIV/0! | AD17: =(D17+N17+R17+Z17)/(B17+L17+P17+X17) -> #DIV/0! | AE17: =(E17+O17+S17+AA17)/(C17+M17+Q17+Y17) -> #DIV/0! | AJ17: =AH17/AF17 -> #DIV/0! | AK17: =AI17/AG17 -> #DIV/0! | AR17: =AO17/AL17 -> #DIV/0! | AS17: =AP17/AM17 -> #DIV/0! | AT17: =AQ17/AN17 -> #DIV/0! | AU17: =T17+X17+Y17+AF17+AG17+AL17+AM17+AN17 -> 0 | AV17: =U17+Z17+AA17+AH17+AI17+AO17+AP17+AQ17 -> 0
A18: 合计 | B18: =SUM(B6:B16) -> 4921 | C18: =SUM(C6:C16) -> 109545 | D18: =SUM(D6:D16) -> 67559 | E18: =SUM(E6:E16) -> 1752946 | F18: =SUM(F6:F16) -> 0 | G18: =SUM(G6:G16) -> 0 | H18: =SUM(H6:H16) -> 30000 | I18: =SUM(I6:I16) -> 255000 | ... U18: =SUM(U6:U16) -> 5919832 | V18: =(D18+N18+R18)/(B18+L18+P18) -> 16.765828 | W18: =(E18+O18+S18)/(C18+M18+Q18) -> 20.985916 | X18: =SUM(X6:X16) -> 2037 | Y18: =SUM(Y6:Y16) -> 47918 | Z18: =SUM(Z6:Z16) -> 25560 | AA18: =SUM(AA6:AA16) -> 579812 | AB18: =Z18/X18 -> 12.547865 | AC18: =AA18/Y18 -> 12.100088 | AD18: =(D18+N18+R18+Z18)/(B18+L18+P18+X18) -> 16.604026 | AE18: =(E18+O18+S18+AA18)/(C18+M18+Q18+Y18) -> 19.447014 | AF18: =SUM(AF6:AF16) -> 0 | AG18: =SUM(AG6:AG16) -> 0 | AH18: =SUM(AH6:AH16) -> 0 | AI18: =SUM(AI6:AI16) -> 0 | AJ18: =AH18/AF18 -> #DIV/0! | AK18: =AI18/AG18 -> #DIV/0! | AL18: =SUM(AL6:AL17) -> 0 | AM18: =SUM(AM6:AM17) -> 0 | AN18: =SUM(AN6:AN17) -> 0 | AO18: =SUM(AO6:AO17) -> 0 | AP18: =SUM(AP6:AP17) -> 0 | AQ18: =SUM(AQ6:AQ17) -> 0 | AR18: =SUM(AR6:AR17) -> #DIV/0! | AS18: =SUM(AS6:AS17) -> #DIV/0! | ... AX18: =SUM(AX6:AX17) -> 54475
AE21: =T14+X14+Y14+AG14 -> 0
AE22: =T15+X15+Y15+AG15 -> 0
AH23: =U16+AA16+Z16+AI16 -> 0
AC25: =T14+X14+Y14+AG14 -> 0
AC26: =T15+X15+Y15+AG15 -> 0
AC27: =T16+X16+Y16+AG16 -> 0
AC28: =T18+X18+Y18+AG18+AL18+AM18+AN18 -> 359787

Sheet 26年新历销售
A1: 2026年（新历）昆明统一生物蝴蝶兰销售数量统计
A2: 月份 | C2: 小街基地 | Y2: 斗南门市 | AD2: 两处平均单价（花） | AG2: 砚山基地 | AL2: 染色花 | AU2: 合计发货数量 | AV2: 合计发货金额 | AW2: 切花合计发货数量 | AX2: 切花合计发货金额
B3: 国内数量 | D3: 金额 | F3: 国外 | T3: 小街销售数量合计 | U3: 金额合计 | V3: 小街平均单价（花） | X3: 斗南销售数量 | Z3: 斗南销售金额 | AB3: 斗南平均单价 | AF3: 砚山销售数量 | AH3: 砚山销售金额 | AJ3: 砚山平均单价 | AL3: 染色花销售数量 | AO3: 染色花销售金额 | AR3: 染色花平均单价
B4: 小花 | C4: 大花 | D4: 小 | E4: 大 | F4: 小苗数量 | G4: 金额 | H4: 中苗数量 | I4: 金额 | J4: 大苗数量 | K4: 金额 | L4: 俄罗斯数量 | N4: 金额 | P4: 国外数量 | R4: 国外金额
L5: 小 | M5: 大 | N5: 小 | O5: 大 | P5: 小 | Q5: 大 | R5: 小 | S5: 大 | V5: 小 | W5: 大 | X5: 小 | Y5: 大 | Z5: 小 | AA5: 大 | AB5: 小 | AC5: 大 | AD5: 小花 | AE5: 大花 | AF5: 小 | AG5: 大 | AH5: 小 | AI5: 大 | AJ5: 小 | AK5: 大 | AL5: 2.8 | AM5: 3 | AN5: 3.5 | AO5: 2.8 | AP5: 3 | AQ5: 3.5 | AR5: 2.8 | AS5: 3 | AT5: 3.5
A6: 1月 | B6: 3068 | C6: 56074 | D6: 56926 | E6: =1118876-1604 -> 1117272 | J6: 1458 | K6: 5103 | P6: 1706 | Q6: 102167 | R6: 30822 | S6: 2402064 | T6: =C6+F6+H6+J6+M6+Q6+B6+L6+P6 -> 164473 | U6: =E6+G6+I6+K6+O6+S6+D6+N6+R6 -> 3612187 | V6: =(D6+N6+R6)/(B6+L6+P6) -> 18.380394 | W6: =(E6+O6+S6)/(C6+M6+Q6) -> 22.240355 | X6: 649 | Y6: 19906 | Z6: 11591 | AA6: 397308 | AB6: =Z6/X6 -> 17.859784 | AC6: =AA6/Y6 -> 19.959208 | AD6: =(D6+N6+R6+Z6)/(B6+L6+P6+X6) -> 18.31809 | AE6: =(E6+O6+S6+AA6)/(C6+M6+Q6+Y6) -> 21.985461 | AG6: 103 | AI6: 3124 | AJ6: =AH6/AF6 -> #DIV/0! | AK6: =AI6/AG6 -> 30.330097 | AL6: 1136 | AM6: 690 | AN6: 1833 | AO6: 43825 | AP6: 27050 | AQ6: 90810 | AR6: =AO6/AL6 -> 38.578345 | AS6: =AP6/AM6 -> 39.202899 | AT6: =AQ6/AN6 -> 49.541735 | AU6: =T6+X6+Y6+AF6+AG6+AL6+AM6+AN6 -> 188790 | AV6: =U6+Z6+AA6+AH6+AI6+AO6+AP6+AQ6 -> 4185895 | AW6: 2115 | AX6: 34266
A7: 2月 | B7: 1471 | C7: 89360 | D7: 21834 | E7: 1571255 | L7: 6000 | M7: 9940 | N7: 100800 | O7: 198800 | P7: =216+1032 -> 1248 | Q7: =73275+57+55 -> 73387 | R7: =3888+17316 -> 21204 | S7: =1621380+1425+720 -> 1623525 | T7: =C7+F7+H7+J7+M7+Q7+B7+L7+P7 -> 181406 | U7: =E7+G7+I7+K7+O7+S7+D7+N7+R7 -> 3537418 | V7: =(D7+N7+R7)/(B7+L7+P7) -> 16.497075 | W7: =(E7+O7+S7)/(C7+M7+Q7) -> 19.651624 | X7: 146 | Y7: 35911 | Z7: 2575 | AA7: 663561 | AB7: =Z7/X7 -> 17.636986 | AC7: =AA7/Y7 -> 18.477932 | AD7: =(D7+N7+R7+Z7)/(B7+L7+P7+X7) -> 16.515849 | AE7: =(E7+O7+S7+AA7)/(C7+M7+Q7+Y7) -> 19.449568 | AI7: 1690 | AJ7: =AH7/AF7 -> #DIV/0! | AK7: =AI7/AG7 -> #DIV/0! | AL7: 14 | AM7: 45 | AN7: 1241 | AO7: 620 | AP7: 1640 | AQ7: 59925 | AR7: =AO7/AL7 -> 44.285714 | AS7: =AP7/AM7 -> 36.444444 | AT7: =AQ7/AN7 -> 48.287671 | AU7: =T7+X7+Y7+AF7+AG7+AL7+AM7+AN7 -> 218763 | AV7: =U7+Z7+AA7+AH7+AI7+AO7+AP7+AQ7 -> 4267429 | AW7: 12432 | AX7: 197487.21
A8: 3月 | B8: 2849 | C8: 29883 | D8: 36102 | E8: =393354-120 -> 393234 | J8: 8790 | K8: 168486 | L8: 16832 | M8: 14720 | N8: 282777.6 | O8: =356440+2800 -> 359240 | Q8: 2100 | S8: 51960 | T8: =B8+C8+F8+H8+J8+L8+M8+P8+Q8 -> 75174 | U8: =D8+E8+G8+I8+K8+N8+O8+R8+S8 -> 1291799.6 | V8: 16.195648 | W8: 17.128397 | X8: 958 | Y8: 10150 | Z8: 7552 | AA8: 140267 | AB8: 7.8830898 | AC8: 13.98658 | AD8: 15.805265 | AE8: 16.557758 | AI8: 120 | AJ8: #DIV/0! | AK8: #DIV/0! | AM8: 7 | AN8: 181 | AP8: 245 | AQ8: 6346 | AR8: #DIV/0! | AS8: 35 | AT8: 35.060773 | AU8: =T8+X8+Y8+AF8+AG8+AL8+AM8+AN8 -> 86470 | AV8: =U8+Z8+AA8+AH8+AI8+AO8+AP8+AQ8 -> 1446329.6 | AW8: 6254 | AX8: 42480
A9: 4月 | B9: 5669 | C9: 42106 | D9: 79641 | E9: =746469+250 -> 746719 | H9: 65048 | I9: 510396 | P9: 288 | Q9: 3324 | R9: 4608 | S9: 83145.5 | T9: =C9+F9+H9+J9+M9+Q9+B9+L9+P9 -> 116435 | U9: =E9+G9+I9+K9+O9+S9+D9+N9+R9 -> 1424509.5 | V9: =(D9+N9+R9)/(B9+L9+P9) -> 14.142857 | W9: =(E9+O9+S9)/(C9+M9+Q9) -> 18.266883 | X9: 1200 | Y9: 7262 | Z9: 15993 | AA9: 120786 | AB9: =Z9/X9 -> 13.3275 | AC9: =AA9/Y9 -> 16.632608 | AD9: =(D9+N9+R9+Z9)/(B9+L9+P9+X9) -> 14.006148 | AE9: =(E9+O9+S9+AA9)/(C9+M9+Q9+Y9) -> 18.041648 | AJ9: =AH9/AF9 -> #DIV/0! | AK9: =AI9/AG9 -> #DIV/0! | AR9: =AO9/AL9 -> #DIV/0! | AS9: =AP9/AM9 -> #DIV/0! | AT9: =AQ9/AN9 -> #DIV/0! | AU9: =T9+X9+Y9+AF9+AG9+AL9+AM9+AN9 -> 124897 | AV9: =U9+Z9+AA9+AH9+AI9+AO9+AP9+AQ9 -> 1561288.5 | AW9: 988 | AX9: 6765
A10: 5月 | B10: 6966 | C10: =27477-72 -> 27405 | D10: 84796 | E10: =451403-1008-900 -> 449495 | P10: 2260 | Q10: 4236 | R10: 40528 | S10: 95494 | T10: =C10+F10+H10+J10+M10+Q10+B10+L10+P10 -> 40867 | U10: =E10+G10+I10+K10+O10+S10+D10+N10+R10 -> 670313 | V10: =(D10+N10+R10)/(B10+L10+P10) -> 13.583785 | W10: =(E10+O10+S10)/(C10+M10+Q10) -> 17.22414 | X10: 1810 | Y10: 6320 | Z10: 22671 | AA10: 104183 | AB10: =Z10/X10 -> 12.525414 | AC10: =AA10/Y10 -> 16.484652 | AD10: =(D10+N10+R10+Z10)/(B10+L10+P10+X10) -> 13.410203 | AE10: =(E10+O10+S10+AA10)/(C10+M10+Q10+Y10) -> 17.101025 | AJ10: =AH10/AF10 -> #DIV/0! | AK10: =AI10/AG10 -> #DIV/0! | AR10: =AO10/AL10 -> #DIV/0! | AS10: =AP10/AM10 -> #DIV/0! | AT10: =AQ10/AN10 -> #DIV/0! | AU10: =T10+X10+Y10+AF10+AG10+AL10+AM10+AN10 -> 48997 | AV10: =U10+Z10+AA10+AH10+AI10+AO10+AP10+AQ10 -> 797167 | AW10: 10303 | AX10: 67555
A11: 5.26-6.10 | B11: ='26数据'!B6 -> 2206 | C11: ='26数据'!B7 -> 17812 | D11: ='26数据'!C6 -> 30053 | E11: ='26数据'!C7 -> 314316 | P11: ='26数据'!B4 -> 1940 | Q11: ='26数据'!B5 -> 4100 | R11: ='26数据'!C4 -> 32456 | S11: ='26数据'!C5 -> 102424 | T11: =C11+F11+H11+J11+M11+Q11+B11+L11+P11 -> 26058 | U11: =E11+G11+I11+K11+O11+S11+D11+N11+R11 -> 479249 | V11: =(D11+N11+R11)/(B11+L11+P11) -> 15.076942 | W11: =(E11+O11+S11)/(C11+M11+Q11) -> 19.018802 | X11: ='26数据'!B8 -> 613 | Y11: ='26数据'!B9 -> 3720 | Z11: ='26数据'!C8 -> 9203 | AA11: ='26数据'!C9 -> 60496 | AB11: =Z11/X11 -> 15.013051 | AC11: =AA11/Y11 -> 16.262366 | AD11: =(D11+N11+R11+Z11)/(B11+L11+P11+X11) -> 15.068712 | AE11: =(E11+O11+S11+AA11)/(C11+M11+Q11+Y11) -> 18.618758 | AJ11: =AH11/AF11 -> #DIV/0! | AK11: =AI11/AG11 -> #DIV/0! | AR11: =AO11/AL11 -> #DIV/0! | AS11: =AP11/AM11 -> #DIV/0! | AT11: =AQ11/AN11 -> #DIV/0! | AU11: =T11+X11+Y11+AF11+AG11+AL11+AM11+AN11 -> 30391 | AV11: =U11+Z11+AA11+AH11+AI11+AO11+AP11+AQ11 -> 548948 | AW11: ='26数据'!B15 -> 1940 | AX11: ='26数据'!C15 -> 9490
T12: =C12+F12+H12+J12+M12+Q12+B12+L12+P12 -> 0 | U12: =E12+G12+I12+K12+O12+S12+D12+N12+R12 -> 0 | V12: =(D12+N12+R12)/(B12+L12+P12) -> #DIV/0! | W12: =(E12+O12+S12)/(C12+M12+Q12) -> #DIV/0! | AB12: =Z12/X12 -> #DIV/0! | AC12: =AA12/Y12 -> #DIV/0! | AD12: =(D12+N12+R12+Z12)/(B12+L12+P12+X12) -> #DIV/0! | AE12: =(E12+O12+S12+AA12)/(C12+M12+Q12+Y12) -> #DIV/0! | AJ12: =AH12/AF12 -> #DIV/0! | AK12: =AI12/AG12 -> #DIV/0! | AR12: =AO12/AL12 -> #DIV/0! | AS12: =AP12/AM12 -> #DIV/0! | AT12: =AQ12/AN12 -> #DIV/0! | AU12: =T12+X12+Y12+AF12+AG12+AL12+AM12+AN12 -> 0 | AV12: =U12+Z12+AA12+AH12+AI12+AO12+AP12+AQ12 -> 0
T13: =C13+F13+H13+J13+M13+Q13+B13+L13+P13 -> 0 | U13: =E13+G13+I13+K13+O13+S13+D13+N13+R13 -> 0 | V13: =(D13+N13+R13)/(B13+L13+P13) -> #DIV/0! | W13: =(E13+O13+S13)/(C13+M13+Q13) -> #DIV/0! | AB13: =Z13/X13 -> #DIV/0! | AC13: =AA13/Y13 -> #DIV/0! | AD13: =(D13+N13+R13+Z13)/(B13+L13+P13+X13) -> #DIV/0! | AE13: =(E13+O13+S13+AA13)/(C13+M13+Q13+Y13) -> #DIV/0! | AJ13: =AH13/AF13 -> #DIV/0! | AK13: =AI13/AG13 -> #DIV/0! | AR13: =AO13/AL13 -> #DIV/0! | AS13: =AP13/AM13 -> #DIV/0! | AT13: =AQ13/AN13 -> #DIV/0! | AU13: =T13+X13+Y13+AF13+AG13+AL13+AM13+AN13 -> 0 | AV13: =U13+Z13+AA13+AH13+AI13+AO13+AP13+AQ13 -> 0
T14: =C14+F14+H14+J14+M14+Q14+B14+L14+P14 -> 0 | U14: =E14+G14+I14+K14+O14+S14+D14+N14+R14 -> 0 | V14: =(D14+N14+R14)/(B14+L14+P14) -> #DIV/0! | W14: =(E14+O14+S14)/(C14+M14+Q14) -> #DIV/0! | AB14: =Z14/X14 -> #DIV/0! | AC14: =AA14/Y14 -> #DIV/0! | AD14: =(D14+N14+R14+Z14)/(B14+L14+P14+X14) -> #DIV/0! | AE14: =(E14+O14+S14+AA14)/(C14+M14+Q14+Y14) -> #DIV/0! | AJ14: =AH14/AF14 -> #DIV/0! | AK14: =AI14/AG14 -> #DIV/0! | AR14: =AO14/AL14 -> #DIV/0! | AS14: =AP14/AM14 -> #DIV/0! | AT14: =AQ14/AN14 -> #DIV/0! | AU14: =T14+X14+Y14+AF14+AG14+AL14+AM14+AN14 -> 0 | AV14: =U14+Z14+AA14+AH14+AI14+AO14+AP14+AQ14 -> 0
T15: =C15+F15+H15+J15+M15+Q15+B15+L15+P15 -> 0 | U15: =E15+G15+I15+K15+O15+S15+D15+N15+R15 -> 0 | V15: =(D15+N15+R15)/(B15+L15+P15) -> #DIV/0! | W15: =(E15+O15+S15)/(C15+M15+Q15) -> #DIV/0! | AB15: =Z15/X15 -> #DIV/0! | AC15: =AA15/Y15 -> #DIV/0! | AD15: =(D15+N15+R15+Z15)/(B15+L15+P15+X15) -> #DIV/0! | AE15: =(E15+O15+S15+AA15)/(C15+M15+Q15+Y15) -> #DIV/0! | AJ15: =AH15/AF15 -> #DIV/0! | AK15: =AI15/AG15 -> #DIV/0! | AR15: =AO15/AL15 -> #DIV/0! | AS15: =AP15/AM15 -> #DIV/0! | AT15: =AQ15/AN15 -> #DIV/0! | AU15: =T15+X15+Y15+AF15+AG15+AL15+AM15+AN15 -> 0 | AV15: =U15+Z15+AA15+AH15+AI15+AO15+AP15+AQ15 -> 0
T16: =C16+F16+H16+J16+M16+Q16+B16+L16+P16 -> 0 | U16: =E16+G16+I16+K16+O16+S16+D16+N16+R16 -> 0 | V16: =(D16+N16+R16)/(B16+L16+P16) -> #DIV/0! | W16: =(E16+O16+S16)/(C16+M16+Q16) -> #DIV/0! | AB16: =Z16/X16 -> #DIV/0! | AC16: =AA16/Y16 -> #DIV/0! | AD16: =(D16+N16+R16+Z16)/(B16+L16+P16+X16) -> #DIV/0! | AE16: =(E16+O16+S16+AA16)/(C16+M16+Q16+Y16) -> #DIV/0! | AJ16: =AH16/AF16 -> #DIV/0! | AK16: =AI16/AG16 -> #DIV/0! | AR16: =AO16/AL16 -> #DIV/0! | AS16: =AP16/AM16 -> #DIV/0! | AT16: =AQ16/AN16 -> #DIV/0! | AU16: =T16+X16+Y16+AF16+AG16+AL16+AM16+AN16 -> 0 | AV16: =U16+Z16+AA16+AH16+AI16+AO16+AP16+AQ16 -> 0
T17: =C17+F17+H17+J17+M17+Q17+B17+L17+P17 -> 0 | U17: =E17+G17+I17+K17+O17+S17+D17+N17+R17 -> 0 | V17: =(D17+N17+R17)/(B17+L17+P17) -> #DIV/0! | W17: =(E17+O17+S17)/(C17+M17+Q17) -> #DIV/0! | AB17: =Z17/X17 -> #DIV/0! | AC17: =AA17/Y17 -> #DIV/0! | AD17: =(D17+N17+R17+Z17)/(B17+L17+P17+X17) -> #DIV/0! | AE17: =(E17+O17+S17+AA17)/(C17+M17+Q17+Y17) -> #DIV/0! | AJ17: =AH17/AF17 -> #DIV/0! | AK17: =AI17/AG17 -> #DIV/0! | AR17: =AO17/AL17 -> #DIV/0! | AS17: =AP17/AM17 -> #DIV/0! | AT17: =AQ17/AN17 -> #DIV/0! | AU17: =T17+X17+Y17+AF17+AG17+AL17+AM17+AN17 -> 0 | AV17: =U17+Z17+AA17+AH17+AI17+AO17+AP17+AQ17 -> 0
A18: 合计 | B18: =SUM(B6:B17) -> 22229 | C18: =SUM(C6:C17) -> 262640 | D18: =SUM(D6:D17) -> 309352 | E18: =SUM(E6:E17) -> 4592291 | F18: =SUM(F6:F17) -> 0 | G18: =SUM(G6:G17) -> 0 | H18: =SUM(H6:H17) -> 65048 | I18: =SUM(I6:I17) -> 510396 | ... U18: =SUM(U6:U17) -> 11015476 | V18: =(D18+N18+R18)/(B18+L18+P18) -> 15.666678 | W18: =(E18+O18+S18)/(C18+M18+Q18) -> 19.951037 | X18: =SUM(X6:X17) -> 5376 | Y18: =SUM(Y6:Y17) -> 83269 | Z18: =SUM(Z6:Z17) -> 69585 | AA18: =SUM(AA6:AA17) -> 1486601 | AB18: =Z18/X18 -> 12.943638 | AC18: =AA18/Y18 -> 17.852995 | AD18: =(D18+N18+R18+Z18)/(B18+L18+P18+X18) -> 15.413753 | AE18: =(E18+O18+S18+AA18)/(C18+M18+Q18+Y18) -> 19.639004 | AF18: =SUM(AF6:AF17) -> 0 | AG18: =SUM(AG6:AG17) -> 103 | AH18: =SUM(AH6:AH17) -> 0 | AI18: =SUM(AI6:AI17) -> 4934 | AJ18: =AH18/AF18 -> #DIV/0! | AK18: =AI18/AG18 -> 47.902913 | AL18: =SUM(AL6:AL17) -> 1150 | AM18: =SUM(AM6:AM17) -> 742 | AN18: =SUM(AN6:AN17) -> 3255 | AO18: =SUM(AO6:AO17) -> 44445 | AP18: =SUM(AP6:AP17) -> 28935 | AQ18: =SUM(AQ6:AQ17) -> 157081 | AR18: =SUM(AR6:AR17) -> #DIV/0! | AS18: =SUM(AS6:AS17) -> #DIV/0! | AT18: =SUM(AT6:AT17) -> #DIV/0! | AU18: =T18+X18+Y18+AF18+AG18+AL18+AM18+AN18 -> 698308 | AV18: =U18+Z18+AA18+AH18+AI18+AO18+AP18+AQ18 -> 12807057 | AW18: =SUM(AW6:AW17) -> 34032 | AX18: =SUM(AX6:AX17) -> 358043.21
AV20: =AU18+AW18 -> 732340
U21: =E7+O7+S7 -> 3393580 | AW21: =AV8+AX8 -> 1488809.6 | AX21: 33976
AW22: =AV9+AX9 -> 1568053.5 | AX22: 14783

Sheet 26年农历销售
A1: 2026年（农历）昆明统一生物蝴蝶兰销售数量统计
A2: 月份 | C2: 小街基地 | Y2: 斗南门市 | AD2: 两处平均单价（花） | AG2: 砚山基地 | AL2: 染色花 | AU2: 合计发货数量 | AV2: 合计发货金额 | AW2: 切花合计发货数量 | AX2: 切花合计发货金额
B3: 国内数量 | D3: 金额 | F3: 国外 | T3: 小街销售数量合计 | U3: 金额合计 | V3: 小街平均单价（花） | X3: 斗南销售数量 | Z3: 斗南销售金额 | AB3: 斗南平均单价 | AF3: 砚山销售数量 | AH3: 砚山销售金额 | AJ3: 砚山平均单价 | AL3: 染色花销售数量 | AO3: 染色花销售金额 | AR3: 染色花平均单价
B4: 小花 | C4: 大花 | D4: 小 | E4: 大 | F4: 小苗数量 | G4: 金额 | H4: 中苗数量 | I4: 金额 | J4: 大苗数量 | K4: 金额 | L4: 俄罗斯数量 | N4: 金额 | P4: 国外数量 | R4: 国外金额
L5: 小 | M5: 大 | N5: 小 | O5: 大 | P5: 小 | Q5: 大 | R5: 小 | S5: 大 | V5: 小 | W5: 大 | X5: 小 | Y5: 大 | Z5: 小 | AA5: 大 | AB5: 小 | AC5: 大 | AD5: 小花 | AE5: 大花 | AF5: 小 | AG5: 大 | AH5: 小 | AI5: 大 | AJ5: 小 | AK5: 大 | AL5: 2.8 | AM5: 3 | AN5: 3.5 | AO5: 2.8 | AP5: 3 | AQ5: 3.5 | AR5: 2.8 | AS5: 3 | AT5: 3.5
A6: 2.17-2.25 | B6: 264 | C6: 7347 | D6: 3132 | E6: 111530 | T6: =C6+F6+H6+J6+M6+Q6+B6+L6+P6 -> 7611 | U6: =E6+G6+I6+K6+O6+S6+D6+N6+R6 -> 114662 | V6: =(D6+N6+R6)/(B6+L6+P6) -> 11.863636 | W6: =(E6+O6+S6)/(C6+M6+Q6) -> 15.180346 | X6: 216 | Y6: 3618 | Z6: 3456 | AA6: 68143 | AB6: =Z6/X6 -> 16 | AC6: =AA6/Y6 -> 18.834439 | AD6: =(D6+N6+R6+Z6)/(B6+L6+P6+X6) -> 13.725 | AE6: =(E6+O6+S6+AA6)/(C6+M6+Q6+Y6) -> 16.386047 | AJ6: =AH6/AF6 -> #DIV/0! | AK6: =AI6/AG6 -> #DIV/0! | AR6: =AO6/AL6 -> #DIV/0! | AS6: =AP6/AM6 -> #DIV/0! | AT6: =AQ6/AN6 -> #DIV/0! | AU6: =T6+X6+Y6+AF6+AG6+AL6+AM6+AN6 -> 11445 | AV6: =U6+Z6+AA6+AH6+AI6+AO6+AP6+AQ6 -> 186261 | AW6: 2115 | AX6: 34266
A7: 3月 | B7: 2849 | C7: 29883 | D7: 36102 | E7: =393354-120 -> 393234 | J7: 8790 | K7: 168486 | L7: 16832 | M7: 14720 | N7: 282777.6 | O7: =356440+2800 -> 359240 | Q7: 2100 | S7: 51960 | T7: =B7+C7+F7+H7+J7+L7+M7+P7+Q7 -> 75174 | U7: =D7+E7+G7+I7+K7+N7+O7+R7+S7 -> 1291799.6 | V7: 16.195648 | W7: 17.128397 | X7: 958 | Y7: 10150 | Z7: 7552 | AA7: 140267 | AB7: 7.8830898 | AC7: 13.98658 | AD7: 15.805265 | AE7: 16.557758 | AI7: 120 | AJ7: #DIV/0! | AK7: #DIV/0! | AM7: 7 | AN7: 181 | AP7: 245 | AQ7: 6346 | AR7: #DIV/0! | AS7: 35 | AT7: 35.060773 | AU7: =T7+X7+Y7+AF7+AG7+AL7+AM7+AN7 -> 86470 | AV7: =U7+Z7+AA7+AH7+AI7+AO7+AP7+AQ7 -> 1446329.6 | AW7: 6254 | AX7: 42480
A8: 4月 | B8: 5669 | C8: 42106 | D8: 79641 | E8: =746469+250 -> 746719 | H8: 65048 | I8: 510396 | P8: 288 | Q8: 3324 | R8: 4608 | S8: 83145.5 | T8: =C8+F8+H8+J8+M8+Q8+B8+L8+P8 -> 116435 | U8: =E8+G8+I8+K8+O8+S8+D8+N8+R8 -> 1424509.5 | V8: =(D8+N8+R8)/(B8+L8+P8) -> 14.142857 | W8: =(E8+O8+S8)/(C8+M8+Q8) -> 18.266883 | X8: 1200 | Y8: 7262 | Z8: 15993 | AA8: 120786 | AB8: =Z8/X8 -> 13.3275 | AC8: =AA8/Y8 -> 16.632608 | AD8: =(D8+N8+R8+Z8)/(B8+L8+P8+X8) -> 14.006148 | AE8: =(E8+O8+S8+AA8)/(C8+M8+Q8+Y8) -> 18.041648 | AJ8: =AH8/AF8 -> #DIV/0! | AK8: =AI8/AG8 -> #DIV/0! | AR8: =AO8/AL8 -> #DIV/0! | AS8: =AP8/AM8 -> #DIV/0! | AT8: =AQ8/AN8 -> #DIV/0! | AU8: =T8+X8+Y8+AF8+AG8+AL8+AM8+AN8 -> 124897 | AV8: =U8+Z8+AA8+AH8+AI8+AO8+AP8+AQ8 -> 1561288.5 | AW8: 988 | AX8: 6765
A9: 5月 | B9: 6966 | C9: =27477-72 -> 27405 | D9: 84796 | E9: =451403-1008-900 -> 449495 | P9: 2260 | Q9: 4236 | R9: 40528 | S9: 95494 | T9: =C9+F9+H9+J9+M9+Q9+B9+L9+P9 -> 40867 | U9: =E9+G9+I9+K9+O9+S9+D9+N9+R9 -> 670313 | V9: =(D9+N9+R9)/(B9+L9+P9) -> 13.583785 | W9: =(E9+O9+S9)/(C9+M9+Q9) -> 17.22414 | X9: 1810 | Y9: 6320 | Z9: 22671 | AA9: 104183 | AB9: =Z9/X9 -> 12.525414 | AC9: =AA9/Y9 -> 16.484652 | AD9: =(D9+N9+R9+Z9)/(B9+L9+P9+X9) -> 13.410203 | AE9: =(E9+O9+S9+AA9)/(C9+M9+Q9+Y9) -> 17.101025 | AJ9: =AH9/AF9 -> #DIV/0! | AK9: =AI9/AG9 -> #DIV/0! | AR9: =AO9/AL9 -> #DIV/0! | AS9: =AP9/AM9 -> #DIV/0! | AT9: =AQ9/AN9 -> #DIV/0! | AU9: =T9+X9+Y9+AF9+AG9+AL9+AM9+AN9 -> 48997 | AV9: =U9+Z9+AA9+AH9+AI9+AO9+AP9+AQ9 -> 797167 | AW9: 10303 | AX9: 67555
A10: 5.26-6.10 | B10: 2206 | C10: 17812 | D10: 30053 | E10: 314316 | P10: 1940 | Q10: 4100 | R10: 32456 | S10: 102424 | T10: 26058 | U10: 479249 | V10: 15.076942 | W10: 19.018802 | X10: 613 | Y10: 3720 | Z10: 9203 | AA10: 60496 | AB10: 15.013051 | AC10: 16.262366 | AD10: 15.068712 | AE10: 18.618758 | AJ10: #DIV/0! | AK10: #DIV/0! | AR10: #DIV/0! | AS10: #DIV/0! | AT10: #DIV/0! | AU10: 30391 | AV10: 548948 | AW10: 1940 | AX10: 9490
T11: =C11+F11+H11+J11+M11+Q11+B11+L11+P11 -> 0 | U11: =E11+G11+I11+K11+O11+S11+D11+N11+R11 -> 0 | V11: =(D11+N11+R11)/(B11+L11+P11) -> #DIV/0! | W11: =(E11+O11+S11)/(C11+M11+Q11) -> #DIV/0! | AB11: =Z11/X11 -> #DIV/0! | AC11: =AA11/Y11 -> #DIV/0! | AD11: =(D11+N11+R11+Z11)/(B11+L11+P11+X11) -> #DIV/0! | AE11: =(E11+O11+S11+AA11)/(C11+M11+Q11+Y11) -> #DIV/0! | AJ11: =AH11/AF11 -> #DIV/0! | AK11: =AI11/AG11 -> #DIV/0! | AR11: =AO11/AL11 -> #DIV/0! | AS11: =AP11/AM11 -> #DIV/0! | AT11: =AQ11/AN11 -> #DIV/0! | AU11: =T11+X11+Y11+AF11+AG11+AL11+AM11+AN11 -> 0 | AV11: =U11+Z11+AA11+AH11+AI11+AO11+AP11+AQ11 -> 0
T12: =C12+F12+H12+J12+M12+Q12+B12+L12+P12 -> 0 | U12: =E12+G12+I12+K12+O12+S12+D12+N12+R12 -> 0 | V12: =(D12+N12+R12)/(B12+L12+P12) -> #DIV/0! | W12: =(E12+O12+S12)/(C12+M12+Q12) -> #DIV/0! | AB12: =Z12/X12 -> #DIV/0! | AC12: =AA12/Y12 -> #DIV/0! | AD12: =(D12+N12+R12+Z12)/(B12+L12+P12+X12) -> #DIV/0! | AE12: =(E12+O12+S12+AA12)/(C12+M12+Q12+Y12) -> #DIV/0! | AJ12: =AH12/AF12 -> #DIV/0! | AK12: =AI12/AG12 -> #DIV/0! | AR12: =AO12/AL12 -> #DIV/0! | AS12: =AP12/AM12 -> #DIV/0! | AT12: =AQ12/AN12 -> #DIV/0! | AU12: =T12+X12+Y12+AF12+AG12+AL12+AM12+AN12 -> 0 | AV12: =U12+Z12+AA12+AH12+AI12+AO12+AP12+AQ12 -> 0
T13: =C13+F13+H13+J13+M13+Q13+B13+L13+P13 -> 0 | U13: =E13+G13+I13+K13+O13+S13+D13+N13+R13 -> 0 | V13: =(D13+N13+R13)/(B13+L13+P13) -> #DIV/0! | W13: =(E13+O13+S13)/(C13+M13+Q13) -> #DIV/0! | AB13: =Z13/X13 -> #DIV/0! | AC13: =AA13/Y13 -> #DIV/0! | AD13: =(D13+N13+R13+Z13)/(B13+L13+P13+X13) -> #DIV/0! | AE13: =(E13+O13+S13+AA13)/(C13+M13+Q13+Y13) -> #DIV/0! | AJ13: =AH13/AF13 -> #DIV/0! | AK13: =AI13/AG13 -> #DIV/0! | AR13: =AO13/AL13 -> #DIV/0! | AS13: =AP13/AM13 -> #DIV/0! | AT13: =AQ13/AN13 -> #DIV/0! | AU13: =T13+X13+Y13+AF13+AG13+AL13+AM13+AN13 -> 0 | AV13: =U13+Z13+AA13+AH13+AI13+AO13+AP13+AQ13 -> 0
T14: =C14+F14+H14+J14+M14+Q14+B14+L14+P14 -> 0 | U14: =E14+G14+I14+K14+O14+S14+D14+N14+R14 -> 0 | V14: =(D14+N14+R14)/(B14+L14+P14) -> #DIV/0! | W14: =(E14+O14+S14)/(C14+M14+Q14) -> #DIV/0! | AB14: =Z14/X14 -> #DIV/0! | AC14: =AA14/Y14 -> #DIV/0! | AD14: =(D14+N14+R14+Z14)/(B14+L14+P14+X14) -> #DIV/0! | AE14: =(E14+O14+S14+AA14)/(C14+M14+Q14+Y14) -> #DIV/0! | AJ14: =AH14/AF14 -> #DIV/0! | AK14: =AI14/AG14 -> #DIV/0! | AR14: =AO14/AL14 -> #DIV/0! | AS14: =AP14/AM14 -> #DIV/0! | AT14: =AQ14/AN14 -> #DIV/0! | AU14: =T14+X14+Y14+AF14+AG14+AL14+AM14+AN14 -> 0 | AV14: =U14+Z14+AA14+AH14+AI14+AO14+AP14+AQ14 -> 0
T15: =C15+F15+H15+J15+M15+Q15+B15+L15+P15 -> 0 | U15: =E15+G15+I15+K15+O15+S15+D15+N15+R15 -> 0 | V15: =(D15+N15+R15)/(B15+L15+P15) -> #DIV/0! | W15: =(E15+O15+S15)/(C15+M15+Q15) -> #DIV/0! | AB15: =Z15/X15 -> #DIV/0! | AC15: =AA15/Y15 -> #DIV/0! | AD15: =(D15+N15+R15+Z15)/(B15+L15+P15+X15) -> #DIV/0! | AE15: =(E15+O15+S15+AA15)/(C15+M15+Q15+Y15) -> #DIV/0! | AJ15: =AH15/AF15 -> #DIV/0! | AK15: =AI15/AG15 -> #DIV/0! | AR15: =AO15/AL15 -> #DIV/0! | AS15: =AP15/AM15 -> #DIV/0! | AT15: =AQ15/AN15 -> #DIV/0! | AU15: =T15+X15+Y15+AF15+AG15+AL15+AM15+AN15 -> 0 | AV15: =U15+Z15+AA15+AH15+AI15+AO15+AP15+AQ15 -> 0
T16: =C16+F16+H16+J16+M16+Q16+B16+L16+P16 -> 0 | U16: =E16+G16+I16+K16+O16+S16+D16+N16+R16 -> 0 | V16: =(D16+N16+R16)/(B16+L16+P16) -> #DIV/0! | W16: =(E16+O16+S16)/(C16+M16+Q16) -> #DIV/0! | AB16: =Z16/X16 -> #DIV/0! | AC16: =AA16/Y16 -> #DIV/0! | AD16: =(D16+N16+R16+Z16)/(B16+L16+P16+X16) -> #DIV/0! | AE16: =(E16+O16+S16+AA16)/(C16+M16+Q16+Y16) -> #DIV/0! | AJ16: =AH16/AF16 -> #DIV/0! | AK16: =AI16/AG16 -> #DIV/0! | AR16: =AO16/AL16 -> #DIV/0! | AS16: =AP16/AM16 -> #DIV/0! | AT16: =AQ16/AN16 -> #DIV/0! | AU16: =T16+X16+Y16+AF16+AG16+AL16+AM16+AN16 -> 0 | AV16: =U16+Z16+AA16+AH16+AI16+AO16+AP16+AQ16 -> 0
T17: =C17+F17+H17+J17+M17+Q17+B17+L17+P17 -> 0 | U17: =E17+G17+I17+K17+O17+S17+D17+N17+R17 -> 0 | V17: =(D17+N17+R17)/(B17+L17+P17) -> #DIV/0! | W17: =(E17+O17+S17)/(C17+M17+Q17) -> #DIV/0! | AB17: =Z17/X17 -> #DIV/0! | AC17: =AA17/Y17 -> #DIV/0! | AD17: =(D17+N17+R17+Z17)/(B17+L17+P17+X17) -> #DIV/0! | AE17: =(E17+O17+S17+AA17)/(C17+M17+Q17+Y17) -> #DIV/0! | AJ17: =AH17/AF17 -> #DIV/0! | AK17: =AI17/AG17 -> #DIV/0! | AR17: =AO17/AL17 -> #DIV/0! | AS17: =AP17/AM17 -> #DIV/0! | AT17: =AQ17/AN17 -> #DIV/0! | AU17: =T17+X17+Y17+AF17+AG17+AL17+AM17+AN17 -> 0 | AV17: =U17+Z17+AA17+AH17+AI17+AO17+AP17+AQ17 -> 0
A18: 合计 | B18: =SUM(B6:B17) -> 17954 | C18: =SUM(C6:C17) -> 124553 | D18: =SUM(D6:D17) -> 233724 | E18: =SUM(E6:E17) -> 2015294 | F18: =SUM(F6:F17) -> 0 | G18: =SUM(G6:G17) -> 0 | H18: =SUM(H6:H17) -> 65048 | I18: =SUM(I6:I17) -> 510396 | ... U18: =SUM(U6:U17) -> 3980533.1 | V18: =(D18+N18+R18)/(B18+L18+P18) -> 15.126893 | W18: =(E18+O18+S18)/(C18+M18+Q18) -> 17.692638 | X18: =SUM(X6:X17) -> 4797 | Y18: =SUM(Y6:Y17) -> 31070 | Z18: =SUM(Z6:Z17) -> 58875 | AA18: =SUM(AA6:AA17) -> 493875 | AB18: =Z18/X18 -> 12.273296 | AC18: =AA18/Y18 -> 15.895558 | AD18: =(D18+N18+R18+Z18)/(B18+L18+P18+X18) -> 14.816287 | AE18: =(E18+O18+S18+AA18)/(C18+M18+Q18+Y18) -> 17.389355 | AF18: =SUM(AF6:AF17) -> 0 | AG18: =SUM(AG6:AG17) -> 0 | AH18: =SUM(AH6:AH17) -> 0 | AI18: =SUM(AI6:AI17) -> 120 | AJ18: =AH18/AF18 -> #DIV/0! | AK18: =AI18/AG18 -> #DIV/0! | AL18: =SUM(AL6:AL17) -> 0 | AM18: =SUM(AM6:AM17) -> 7 | AN18: =SUM(AN6:AN17) -> 181 | AO18: =SUM(AO6:AO17) -> 0 | AP18: =SUM(AP6:AP17) -> 245 | AQ18: =SUM(AQ6:AQ17) -> 6346 | AR18: =SUM(AR6:AR17) -> #DIV/0! | AS18: =SUM(AS6:AS17) -> #DIV/0! | AT18: =SUM(AT6:AT17) -> #DIV/0! | AU18: =T18+X18+Y18+AF18+AG18+AL18+AM18+AN18 -> 302200 | AV18: =U18+Z18+AA18+AH18+AI18+AO18+AP18+AQ18 -> 4539994.1 | AW18: =SUM(AW6:AW17) -> 21600 | AX18: =SUM(AX6:AX17) -> 160556

Sheet 进货验货报告
A1: 批号 | B1: 入库基地 | C1: 进货来源 | D1: 到货日期 | E1: 1.7数量 | F1: 1.7金额 | G1: 2.5寸数量 | H1: 2.5寸金额 | I1: 3数量 | J1: 3金额 | K1: 3.5数量 | L1: 3.5金额 | M1: 3.8数量 | N1: 3.8金额 | O1: 2.8数量 | P1: 2.8金额 | Q1: 总数量 | R1: 总金额 | S1: 备注 | T1: 运费
A2: IQ-26057 | B2: 小街 | C2: 生辉 | D2: 2026.5.28 | I2: 792 | J2: =497*14+249*16+46*0 -> 10942 | Q2: =E2+G2+I2+K2+O2+M2 -> 792 | R2: =F2+H2+J2+L2+P2+N2 -> 10942 | T2: 405
A3: IQ-26058 | B3: 小街 | C3: 佳彩 | D3: 2026.5.28 | K3: 180 | L3: =K3*19 -> 3420 | O3: 48 | P3: =O3*13 -> 624 | Q3: =E3+G3+I3+K3+O3+M3 -> 228 | R3: =F3+H3+J3+L3+P3+N3 -> 4044
A4: IQ-26059 | B4: 小街 | C4: 生辉 | D4: 2026.6.2 | K4: 915 | L4: =K4*13 -> 11895 | Q4: =E4+G4+I4+K4+O4+M4 -> 915 | R4: =F4+H4+J4+L4+P4+N4 -> 11895 | T4: 346
A5: IQ-26060 | B5: 小街 | C5: 绿枫 | D5: 2026.6.4 | K5: 1004 | L5: =K5*12 -> 12048 | O5: 3006 | P5: =O5*7.5 -> 22545 | Q5: =E5+G5+I5+K5+O5+M5 -> 4010 | R5: =F5+H5+J5+L5+P5+N5 -> 34593 | T5: 1387.6
A6: IQ-26061 | B6: 小街 | C6: 生辉 | D6: 2026.6.7 | I6: 1860 | J6: =900*16+960*15 -> 28800 | Q6: =E6+G6+I6+K6+O6+M6 -> 1860 | R6: =F6+H6+J6+L6+P6+N6 -> 28800 | T6: 1027.31
Q7: =E7+G7+I7+K7+O7+M7 -> 0 | R7: =F7+H7+J7+L7+P7+N7 -> 0
Q8: =E8+G8+I8+K8+O8+M8 -> 0 | R8: =F8+H8+J8+L8+P8+N8 -> 0
Q9: =E9+G9+I9+K9+O9+M9 -> 0 | R9: =F9+H9+J9+L9+P9+N9 -> 0
Q10: =E10+G10+I10+K10+O10+M10 -> 0 | R10: =F10+H10+J10+L10+P10+N10 -> 0
Q11: =E11+G11+I11+K11+O11+M11 -> 0 | R11: =F11+H11+J11+L11+P11+N11 -> 0
Q12: =E12+G12+I12+K12+O12+M12 -> 0 | R12: =F12+H12+J12+L12+P12+N12 -> 0
A13: 总计 | E13: =SUM(E2:E12) -> 0 | F13: =SUM(F2:F12) -> 0 | G13: =SUM(G2:G12) -> 0 | H13: =SUM(H2:H12) -> 0 | I13: =SUM(I2:I12) -> 2652 | J13: =SUM(J2:J12) -> 39742 | K13: =SUM(K2:K12) -> 2099 | L13: =SUM(L2:L12) -> 27363 | ... R13: =SUM(R2:R12) -> 90274
J14: 苗 | K14: 长松园 | O14: 苗
K15: 小街 | O15: 开花株
K16: 8号棚 | O16: 合计 | P16: =SUM(P14:P15) -> 0 | Q16: =SUM(Q14:Q15) -> 0
J17: 开花株 | K17: 小街
K18: 8号棚

Sheet 26数据
A1: 本月5.26-6.10发货 | F1: 上月4.26-5.10发货
A2: 种类 | B2: 数量（株） | C2: 金额（元） | D2: 平均单价 | F2: 种类 | G2: 数量（株） | H2: 金额（元） | I2: 平均单价
A3: 苗 | D3: =C3/B3 -> #DIV/0! | F3: 苗 | I3: =H3/G3 -> #DIV/0!
A4: 国外（2.8/3寸） | B4: =1796+144 -> 1940 | C4: =29720+2736 -> 32456 | D4: =C4/B4 -> 16.729897 | F4: 国外（2.8/3寸） | G4: 1588 | H4: 26416 | I4: =H4/G4 -> 16.634761
A5: 国外（3.5寸） | B5: =216+2804+1080 -> 4100 | C5: =4752+70672+27000 -> 102424 | D5: =C5/B5 -> 24.981463 | F5: 国外（3.5寸） | G5: =504+2944 -> 3448 | H5: =11088+62684 -> 73772 | I5: =H5/G5 -> 21.395592
A6: 国内小街（2.8/3寸） | B6: 2206 | C6: 30053 | D6: =C6/B6 -> 13.6233 | F6: 国内小街（2.8/3寸） | G6: 3721 | H6: 48489 | I6: =H6/G6 -> 13.031174
A7: 国内小街（3.5寸） | B7: 17812 | C7: 314316 | D7: =C7/B7 -> 17.646306 | F7: 国内小街（3.5寸） | G7: 14417 | H7: 230184 | I7: =H7/G7 -> 15.966151
A8: 斗南（2.8/3寸） | B8: 613 | C8: 9203 | D8: =C8/B8 -> 15.013051 | F8: 斗南（2.8/3寸） | G8: 1292 | H8: 15749 | I8: =H8/G8 -> 12.189628
A9: 斗南（3.5/3.8寸） | B9: 3720 | C9: 60496 | D9: =C9/B9 -> 16.262366 | F9: 斗南（3.5/3.8寸） | G9: 3741 | H9: 62685 | I9: =H9/G9 -> 16.756215
A10: 砚山（2.8/3寸） | D10: =C10/B10 -> #DIV/0! | F10: 砚山（2.8/3寸） | I10: =H10/G10 -> #DIV/0!
A11: 砚山（3.5/3.8寸） | D11: =C11/B11 -> #DIV/0! | F11: 砚山（3.5/3.8寸） | I11: =H11/G11 -> #DIV/0!
A12: 染色花（2.8寸） | D12: =C12/B12 -> #DIV/0! | F12: 染色花（2.8寸） | I12: =H12/G12 -> #DIV/0!
A13: 染色花（3.0寸） | D13: =C13/B13 -> #DIV/0! | F13: 染色花（3.0寸） | I13: =H13/G13 -> #DIV/0!
A14: 染色花（3.5/3.8寸） | D14: =C14/B14 -> #DIV/0! | F14: 染色花（3.5/3.8寸） | I14: =H14/G14 -> #DIV/0!
A15: 切花 | B15: 1940 | C15: 9490 | D15: =C15/B15 -> 4.8917526 | F15: 切花 | G15: 5168 | H15: 37660 | I15: =H15/G15 -> 7.2871517
A16: 小花 | B16: =B4+B6+B8+B10 -> 4759 | C16: =C4+C6+C8+C10 -> 71712 | D16: =C16/B16 -> 15.068712 | F16: 小花 | G16: =G4+G6+G8+G10 -> 6601 | H16: =H4+H6+H8+H10 -> 90654 | I16: =H16/G16 -> 13.733374
A17: 大花 | B17: =B5+B7+B9+B11 -> 25632 | C17: =C5+C7+C9+C11 -> 477236 | D17: =C17/B17 -> 18.618758 | F17: 大花 | G17: =G5+G7+G9+G11 -> 21606 | H17: =H5+H7+H9+H11 -> 366641 | I17: =H17/G17 -> 16.969407
A18: 开花株小计 | B18: =SUM(B4:B14) -> 30391 | C18: =SUM(C4:C14) -> 548948 | D18: =C18/B18 -> 18.062848 | F18: 开花株小计 | G18: =SUM(G4:G14) -> 28207 | H18: =SUM(H4:H14) -> 457295 | I18: =H18/G18 -> 16.21211
A19: 总计 | B19: =B3+B18+B15 -> 32331 | C19: =C3+C18+C15 -> 558438 | F19: 总计 | G19: =G3+G18+G15 -> 33375 | H19: =H3+H18+H15 -> 494955
A20: 6月同比5月 | B20: 多（株） | C20: 多（元） | D20: 苗多 | E20: 国外 | F20: 小街多 | G20: 斗南 | H20: 切花
B21: =B19-G19 -> -1044 | C21: =C19-H19 -> 63483 | D21: =B3-G3 -> 0 | E21: =(B4+B5)-G4-G5 -> 1004 | F21: =B7+B6-G6-G7 -> 1880 | G21: =B9+B8-G8-G9 -> -700 | H21: =B15-G15 -> -3228
A23: 2026年新历1月-6.10发货
A24: 种类 | B24: 数量（株） | C24: 金额（元） | D24: 平均单价
A25: 苗 | B25: ='26年新历销售'!F18+'26年新历销售'!H18+'26年新历销售'!J18 -> 75296 | C25: ='26年新历销售'!G18+'26年新历销售'!I18+'26年新历销售'!K18 -> 683985 | D25: =C25/B25 -> 9.0839487
A26: 国外（2.8/3寸） | B26: ='26年新历销售'!L18+'26年新历销售'!P18 -> 30274 | C26: ='26年新历销售'!N18+'26年新历销售'!R18 -> 513195.6 | D26: =C26/B26 -> 16.951695 | E26: 截止5.25小花平均单价 | F26: 2025年新历1月-6.10发货
A27: 国外（3.5寸） | B27: ='26年新历销售'!M18+'26年新历销售'!Q18 -> 213974 | C27: ='26年新历销售'!O18+'26年新历销售'!S18 -> 4916652.5 | D27: =C27/B27 -> 22.977803 | E27: 15.44 | F27: 种类 | G27: 数量（株） | H27: 金额（元） | I27: 平均单价
A28: 国内小街（2.8/3寸） | B28: ='26年新历销售'!B18 -> 22229 | C28: ='26年新历销售'!D18 -> 309352 | D28: =C28/B28 -> 13.916595 | E28: 小花同比上周 | F28: 苗 | G28: =新25年新历销售!F18+新25年新历销售!H18+新25年新历销售!J18 -> 30040 | H28: =新25年新历销售!G18+新25年新历销售!I18+新25年新历销售!K18 -> 255690 | I28: =H28/G28 -> 8.5116511
A29: 国内小街（3.5寸） | B29: ='26年新历销售'!C18 -> 262640 | C29: ='26年新历销售'!E18 -> 4592291 | D29: =C29/B29 -> 17.485117 | E29: =D38-E27 -> -0.026247171 | F29: 国外（2.8/3寸） | G29: =新25年新历销售!L18+新25年新历销售!P18 -> 46144 | H29: =新25年新历销售!N18+新25年新历销售!R18 -> 788588 | I29: =H29/G29 -> 17.089719
A30: 斗南（2.8/3寸） | B30: ='26年新历销售'!X18 -> 5376 | C30: ='26年新历销售'!Z18 -> 69585 | D30: =C30/B30 -> 12.943638 | F30: 国外（3.5寸） | G30: =新25年新历销售!M18+新25年新历销售!Q18 -> 259778 | H30: =新25年新历销售!O18+新25年新历销售!S18 -> 6154639 | I30: =H30/G30 -> 23.691918
A31: 斗南（3.5/3.8寸） | B31: ='26年新历销售'!Y18 -> 83269 | C31: ='26年新历销售'!AA18 -> 1486601 | D31: =C31/B31 -> 17.852995 | F31: 国内小街（2.8/3寸） | G31: =新25年新历销售!B18 -> 4921 | H31: =新25年新历销售!D18 -> 67559 | I31: =H31/G31 -> 13.728714
A32: 砚山（2.8/3寸） | D32: =C32/B32 -> #DIV/0! | F32: 国内小街（3.5寸） | G32: =新25年新历销售!C18 -> 182197 | H32: =新25年新历销售!E18 -> 3184604 | I32: =H32/G32 -> 17.478905
A33: 砚山（3.5/3.8寸） | B33: ='26年新历销售'!AG18 -> 103 | C33: ='26年新历销售'!AI18 -> 4934 | D33: =C33/B33 -> 47.902913 | F33: 斗南（2.8/3寸） | G33: =新25年新历销售!X18 -> 2037 | H33: =新25年新历销售!Z18 -> 25560 | I33: =H33/G33 -> 12.547865
A34: 染色花（2.8寸） | B34: ='26年新历销售'!AL18 -> 1150 | C34: ='26年新历销售'!AO18 -> 44445 | D34: =C34/B34 -> 38.647826 | F34: 斗南（3.5/3.8寸） | G34: =新25年新历销售!Y18 -> 80778 | H34: =新25年新历销售!AA18 -> 1129817 | I34: =H34/G34 -> 13.986692
A35: 染色花（3.0寸） | B35: ='26年新历销售'!AM18 -> 742 | C35: ='26年新历销售'!AP18 -> 28935 | D35: =C35/B35 -> 38.995957 | F35: 砚山（2.8/3寸） | G35: =新25年新历销售!AF18 -> 0 | H35: =新25年新历销售!AH18 -> 0 | I35: =H35/G35 -> #DIV/0!
A36: 染色花（3.5/3.8寸） | B36: ='26年新历销售'!AN18 -> 3255 | C36: ='26年新历销售'!AQ18 -> 157081 | D36: =C36/B36 -> 48.258372 | E36: 截止5.25大花平均单价 | F36: 砚山（3.5/3.8寸） | G36: =新25年新历销售!AG18 -> 0 | H36: =新25年新历销售!AI18 -> 0 | I36: =H36/G36 -> #DIV/0!
A37: 切花 | B37: ='26年新历销售'!AW18 -> 34032 | C37: ='26年新历销售'!AX18 -> 358043.21 | D37: =C37/B37 -> 10.520781 | E37: 19.69 | F37: 切花 | G37: =新25年新历销售!AW18 -> 8988 | H37: =新25年新历销售!AX18 -> 63385 | I37: =H37/G37 -> 7.0521807 | J37: 同比2025年
A38: 小花 | B38: =B26+B28+B30+B32 -> 57879 | C38: =C26+C28+C30+C32 -> 892132.6 | D38: =C38/B38 -> 15.413753 | E38: 大花同比上周 | F38: 小花 | G38: =G29+G31+G33+G35 -> 53102 | H38: =H29+H31+H33+H35 -> 881707 | I38: =H38/G38 -> 16.604026 | J38: =D38-I38 -> -1.1902734
A39: 大花 | B39: =B27+B29+B31+B33 -> 559986 | C39: =C27+C29+C31+C33 -> 11000478 | D39: =C39/B39 -> 19.644203 | E39: =D39-E37 -> -0.045797288 | F39: 大花 | G39: =G30+G32+G34+G36 -> 522753 | H39: =H30+H32+H34+H36 -> 10469060 | I39: =H39/G39 -> 20.026781 | J39: =D39-I39 -> -0.38257858
A40: 开花株小计 | B40: =SUM(B26:B36) -> 623012 | C40: =SUM(C26:C36) -> 12123072 | D40: =C40/B40 -> 19.45881 | F40: 开花株小计 | G40: =SUM(G29:G36) -> 575855 | H40: =SUM(H29:H36) -> 11350767 | I40: =H40/G40 -> 19.711155
A41: 总计 | B41: =B25+B40+B37 -> 732340 | C41: =C25+C40+C37 -> 13165100 | F41: 总计 | G41: =G28+G40+G37 -> 614883 | H41: =H28+H40+H37 -> 11669842
...

Sheet 生产
A1: 5.26-6.10发货
A2: 种类 | B2: 数量（株） | C2: 种类 | D2: 数量 | E2: 占比
A3: 苗 | C3: 外调 | D3: 792株 | E3: 0.026 | F3: 占总发货数量
A4: 国外（2.8/3寸） | B4: =1796+144 -> 1940 | D4: BC级株
A5: 国外（3.5寸） | B5: =216+2804+1080 -> 4100
A6: 国内小街（2.8/3寸） | B6: 2206 | C6: 非外调 | D6: 29599株 | E6: 0.9739 | F6: 占总发货数量
A7: 国内小街（3.5寸） | B7: 17812 | D7: BC级5435株 | E7: 18.36
A8: 斗南（2.8/3寸） | B8: 613
A9: 斗南（3.5/3.8寸） | B9: 3720
A10: 砚山（2.8/3寸）
A11: 砚山（3.5/3.8寸）
A12: 染色花（2.8寸）
A13: 染色花（3.0寸）
A14: 染色花（3.5/3.8寸）
A15: 切花 | B15: 1940
A16: 小花 | B16: =B4+B6+B8+B10 -> 4759
A17: 大花 | B17: =B5+B7+B9+B11 -> 25632
A18: 开花株小计 | B18: =SUM(B4:B14) -> 30391
A19: 总计 | B19: =B3+B18+B15 -> 32331

Sheet 24年农历销售
A1: 2024年（农历）昆明统一生物蝴蝶兰销售数量统计
A2: 月份 | B2: 小街基地 | Q2: 斗南门市 | T2: 两处平均单价（花）
B3: 国内数量 | C3: 金额 | D3: 国外 | N3: 小街销售数量合计 | O3: 金额合计 | P3: 小街平均单价（花） | Q3: 斗南销售数量 | R3: 金额 | S3: 斗南平均单价
D4: 小苗数量 | E4: 金额 | F4: 中苗数量 | G4: 金额 | H4: 大苗数量 | I4: 金额 | J4: 俄罗斯数量 | K4: 金额 | L4: 开花株数量 | M4: 金额
A5: 2.9-2.25 | B5: 3216 | C5: 107606 | N5: =B5+D5+F5+H5+J5+L5 -> 3216 | O5: =C5+E5+G5+I5+K5+M5 -> 107606 | P5: =(C5+K5+M5)/(B5+J5+L5) -> 33.459577 | Q5: 4064 | R5: 63939 | S5: =R5/Q5 -> 15.733022 | T5: =(C5+K5+M5+R5)/(B5+J5+L5+Q5) -> 23.563874
A6: 3月 | B6: =42113-32020 -> 10093 | C6: =182605-9420 -> 173185 | D6: 15480 | E6: 93192.7 | F6: 360 | G6: 1320 | H6: =720+168 -> 888 | I6: 7380 | J6: 32020 | K6: 798856 | L6: 0 | M6: 0 | N6: =B6+D6+F6+H6+J6+L6 -> 58841 | O6: =C6+E6+G6+I6+K6+M6 -> 1073933.7 | P6: =(C6+K6+M6)/(B6+J6+L6) -> 23.081732 | Q6: 10854 | R6: 165099 | S6: =R6/Q6 -> 15.21089 | T6: =(C6+K6+M6+R6)/(B6+J6+L6+Q6) -> 21.468839
A7: 4月 | B7: 15916 | C7: 312086.5 | F7: 7002 | G7: 59517 | H7: 19302 | I7: 219486 | J7: 33636 | K7: 832924 | L7: 600 | M7: 16440 | N7: =B7+D7+F7+H7+J7+L7 -> 76456 | O7: =C7+E7+G7+I7+K7+M7 -> 1440453.5 | P7: =(C7+K7+M7)/(B7+J7+L7) -> 23.158608 | Q7: 12588 | R7: 186891 | S7: =R7/Q7 -> 14.846759 | T7: =(C7+K7+M7+R7)/(B7+J7+L7+Q7) -> 21.490939
A8: 5月 | B8: 15352 | C8: 254371 | H8: 660 | I8: 12540 | J8: =33984+16826 -> 50810 | K8: 1240509 | L8: 1034 | M8: 41545 | N8: =B8+D8+F8+H8+J8+L8 -> 67856 | O8: =C8+E8+G8+I8+K8+M8 -> 1548965 | P8: =(C8+K8+M8)/(B8+J8+L8) -> 22.864828 | Q8: 15897 | R8: 190386 | S8: =R8/Q8 -> 11.976222 | T8: =(C8+K8+M8+R8)/(B8+J8+L8+Q8) -> 20.781666
A9: 6月 | B9: 14125 | C9: 209629 | J9: 40516 | K9: 976062 | N9: =B9+D9+F9+H9+J9+L9 -> 54641 | O9: =C9+E9+G9+I9+K9+M9 -> 1185691 | P9: =(C9+K9+M9)/(B9+J9+L9) -> 21.699658 | Q9: 8410 | R9: 108106 | S9: =R9/Q9 -> 12.854459 | T9: =(C9+K9+M9+R9)/(B9+J9+L9+Q9) -> 20.519849
A10: 7月 | B10: 12335 | C10: 191916 | J10: 37822 | K10: =820869+34284+972 -> 856125 | N10: =B10+D10+F10+H10+J10+L10 -> 50157 | O10: =C10+E10+G10+I10+K10+M10 -> 1048041 | P10: =(C10+K10+M10)/(B10+J10+L10) -> 20.895209 | Q10: 7769 | R10: 109402.1 | S10: =R10/Q10 -> 14.081877 | T10: =(C10+K10+M10+R10)/(B10+J10+L10+Q10) -> 19.981409
A11: 8月 | B11: 13888 | C11: 237251 | J11: 94200 | K11: 2201726.5 | N11: =B11+D11+F11+H11+J11+L11 -> 108088 | O11: =C11+E11+G11+I11+K11+M11 -> 2438977.5 | P11: =(C11+K11+M11)/(B11+J11+L11) -> 22.564739 | Q11: 11028 | R11: 140590 | S11: =R11/Q11 -> 12.748458 | T11: =(C11+K11+M11+R11)/(B11+J11+L11+Q11) -> 21.655928
A12: 9月 | B12: 12886 | C12: 236220 | J12: 54036 | K12: 1292695 | N12: =B12+D12+F12+H12+J12+L12 -> 66922 | O12: =C12+E12+G12+I12+K12+M12 -> 1528915 | P12: =(C12+K12+M12)/(B12+J12+L12) -> 22.846224 | Q12: 10016 | R12: =139870+90 -> 139960 | S12: =R12/Q12 -> 13.973642 | T12: =(C12+K12+M12+R12)/(B12+J12+L12+Q12) -> 21.691167
A13: 10月 | B13: 17859 | C13: 344955 | J13: 5540 | K13: 130092 | L13: 20224 | M13: 558530 | N13: =B13+D13+F13+H13+J13+L13 -> 43623 | O13: =C13+E13+G13+I13+K13+M13 -> 1033577 | P13: =(C13+K13+M13)/(B13+J13+L13) -> 23.693396 | Q13: 10083 | R13: 151685 | S13: =R13/Q13 -> 15.043638 | T13: =(C13+K13+M13+R13)/(B13+J13+L13+Q13) -> 22.069452
A14: 11月 | B14: 23369 | C14: 433705 | J14: 61462 | K14: 1510314 | L14: 22227 | M14: 554905 | N14: =B14+D14+F14+H14+J14+L14 -> 107058 | O14: =C14+E14+G14+I14+K14+M14 -> 2498924 | P14: =(C14+K14+M14)/(B14+J14+L14) -> 23.341777 | Q14: 12193 | R14: 184394 | S14: =R14/Q14 -> 15.122939 | T14: =(C14+K14+M14+R14)/(B14+J14+L14+Q14) -> 22.50143
A15: 12月 | B15: 33271 | C15: =699829+612 -> 700441 | J15: =15262 -> 15262 | K15: =356234 -> 356234 | L15: 1328 | M15: 29936 | N15: =B15+D15+F15+H15+J15+L15 -> 49861 | O15: =C15+E15+G15+I15+K15+M15 -> 1086611 | P15: =(C15+K15+M15)/(B15+J15+L15) -> 21.792804 | Q15: 11656 | R15: 193940 | S15: =R15/Q15 -> 16.638641 | T15: =(C15+K15+M15+R15)/(B15+J15+L15+Q15) -> 20.816213
A16: 1月 | B16: 72387 | C16: 1427651 | H16: 40 | I16: 690 | J16: 4992 | K16: 115444 | L16: 118764 | M16: 2655256 | N16: =B16+D16+F16+H16+J16+L16 -> 196183 | O16: =C16+E16+G16+I16+K16+M16 -> 4199041 | P16: =(C16+K16+M16)/(B16+J16+L16) -> 21.404542 | Q16: 32831 | R16: 555715 | S16: =R16/Q16 -> 16.926533 | T16: =(C16+K16+M16+R16)/(B16+J16+L16+Q16) -> 20.762471
N17: =B17+D17+F17+H17+J17+L17 -> 0 | O17: =C17+E17+G17+I17+K17+M17 -> 0 | P17: =(C17+K17+M17)/(B17+J17+L17) -> #DIV/0! | S17: =R17/Q17 -> #DIV/0! | T17: =(C17+K17+M17+R17)/(B17+J17+L17+Q17) -> #DIV/0!
A18: 合计 | B18: =SUM(B5:B17) -> 244697 | C18: =SUM(C5:C17) -> 4629016.5 | D18: =SUM(D5:D17) -> 15480 | E18: =SUM(E5:E17) -> 93192.7 | F18: =SUM(F5:F17) -> 7362 | G18: =SUM(G5:G17) -> 60837 | H18: =SUM(H5:H17) -> 20890 | I18: =SUM(I5:I17) -> 240096 | ... O18: =SUM(O5:O17) -> 19190736 | P18: =(C18+K18+M18)/(B18+J18+L18) -> 22.399049 | Q18: =SUM(Q5:Q17) -> 147389 | R18: =SUM(R5:R17) -> 2190107.1 | S18: =R18/Q18 -> 14.859366 | T18: =(C18+K18+M18+R18)/(B18+J18+L18+Q18) -> 21.272643
O23: =N18+Q18 -> 1030291

Sheet 24年新历销售
A1: 2024年（新历）昆明统一生物蝴蝶兰销售数量统计
A2: 月份 | B2: 小街基地 | Q2: 斗南门市 | T2: 两处平均单价（花）
B3: 国内数量 | C3: 金额 | D3: 国外 | N3: 小街销售数量合计 | O3: 金额合计 | P3: 小街平均单价（花） | Q3: 斗南销售数量 | R3: 金额 | S3: 斗南平均单价
D4: 小苗数量 | E4: 金额 | F4: 中苗数量 | G4: 金额 | H4: 大苗数量 | I4: 金额 | J4: 俄罗斯数量 | K4: 金额 | L4: 开花株数量 | M4: 金额
A5: 1月 | B5: 69157 | C5: 1913341 | H5: 400 | I5: 7500 | L5: 130548 | M5: 2854381.2 | N5: =B5+D5+F5+H5+J5+L5 -> 200105 | O5: =C5+E5+G5+I5+K5+M5 -> 4775222.2 | P5: =(C5+K5+M5)/(B5+J5+L5) -> 23.873825 | Q5: 30279 | R5: 715123 | S5: =R5/Q5 -> 23.617788 | T5: =(C5+K5+M5+R5)/(B5+J5+L5+Q5) -> 23.840116
A6: 2月 | B6: 24025 | C6: 533529 | L6: 1320 | M6: 52769 | N6: =B6+D6+F6+H6+J6+L6 -> 25345 | O6: =C6+E6+G6+I6+K6+M6 -> 586298 | P6: =(C6+K6+M6)/(B6+J6+L6) -> 23.132689 | Q6: 20735 | R6: 438142 | S6: =R6/Q6 -> 21.130552 | T6: =(C6+K6+M6+R6)/(B6+J6+L6+Q6) -> 22.231771
A7: 3月 | B7: =42113-32020 -> 10093 | C7: =182605-9420 -> 173185 | D7: 15480 | E7: 93192.7 | F7: 360 | G7: 1320 | H7: =720+168 -> 888 | I7: 7380 | J7: 32020 | K7: 798856 | L7: 0 | M7: 0 | N7: =B7+D7+F7+H7+J7+L7 -> 58841 | O7: =C7+E7+G7+I7+K7+M7 -> 1073933.7 | P7: =(C7+K7+M7)/(B7+J7+L7) -> 23.081732 | Q7: 10854 | R7: 165099 | S7: =R7/Q7 -> 15.21089 | T7: =(C7+K7+M7+R7)/(B7+J7+L7+Q7) -> 21.468839
A8: 4月 | B8: 15916 | C8: 312086.5 | F8: 7002 | G8: 59517 | H8: 19302 | I8: 219486 | J8: 33636 | K8: 832924 | L8: 600 | M8: 16440 | N8: =B8+D8+F8+H8+J8+L8 -> 76456 | O8: =C8+E8+G8+I8+K8+M8 -> 1440453.5 | P8: =(C8+K8+M8)/(B8+J8+L8) -> 23.158608 | Q8: 12588 | R8: 186891 | S8: =R8/Q8 -> 14.846759 | T8: =(C8+K8+M8+R8)/(B8+J8+L8+Q8) -> 21.490939
A9: 5月 | B9: 15352 | C9: 254371 | H9: 660 | I9: 12540 | J9: =33984+16826 -> 50810 | K9: 1240509 | L9: 1034 | M9: 41545 | N9: =B9+D9+F9+H9+J9+L9 -> 67856 | O9: =C9+E9+G9+I9+K9+M9 -> 1548965 | P9: =(C9+K9+M9)/(B9+J9+L9) -> 22.864828 | Q9: 15897 | R9: 190386 | S9: =R9/Q9 -> 11.976222 | T9: =(C9+K9+M9+R9)/(B9+J9+L9+Q9) -> 20.781666
A10: 6月 | B10: 14125 | C10: 209629 | J10: 40516 | K10: 976062 | N10: =B10+D10+F10+H10+J10+L10 -> 54641 | O10: =C10+E10+G10+I10+K10+M10 -> 1185691 | P10: =(C10+K10+M10)/(B10+J10+L10) -> 21.699658 | Q10: 8410 | R10: 108106 | S10: =R10/Q10 -> 12.854459 | T10: =(C10+K10+M10+R10)/(B10+J10+L10+Q10) -> 20.519849
A11: 7月 | B11: 12335 | C11: 191916 | J11: 37822 | K11: =820869+34284+972 -> 856125 | N11: =B11+D11+F11+H11+J11+L11 -> 50157 | O11: =C11+E11+G11+I11+K11+M11 -> 1048041 | P11: =(C11+K11+M11)/(B11+J11+L11) -> 20.895209 | Q11: 7769 | R11: 109402.1 | S11: =R11/Q11 -> 14.081877 | T11: =(C11+K11+M11+R11)/(B11+J11+L11+Q11) -> 19.981409
A12: 8月 | B12: 13888 | C12: 237251 | J12: 94200 | K12: 2201726.5 | N12: =B12+D12+F12+H12+J12+L12 -> 108088 | O12: =C12+E12+G12+I12+K12+M12 -> 2438977.5 | P12: =(C12+K12+M12)/(B12+J12+L12) -> 22.564739 | Q12: 11028 | R12: 140590 | S12: =R12/Q12 -> 12.748458 | T12: =(C12+K12+M12+R12)/(B12+J12+L12+Q12) -> 21.655928
A13: 9月 | B13: 12886 | C13: 236220 | J13: 54036 | K13: 1292695 | N13: =B13+D13+F13+H13+J13+L13 -> 66922 | O13: =C13+E13+G13+I13+K13+M13 -> 1528915 | P13: =(C13+K13+M13)/(B13+J13+L13) -> 22.846224 | Q13: 10016 | R13: =139870+90 -> 139960 | S13: =R13/Q13 -> 13.973642 | T13: =(C13+K13+M13+R13)/(B13+J13+L13+Q13) -> 21.691167
A14: 10月 | B14: 17859 | C14: 344955 | J14: 5540 | K14: 130092 | L14: 20224 | M14: 558530 | N14: 43623 | O14: 1033577 | P14: 23.693396 | Q14: 10083 | R14: 151685 | S14: 15.043638 | T14: 22.069452
A15: 11月 | B15: 23369 | C15: 433705 | J15: 61462 | K15: 1510314 | L15: 22227 | M15: 554905 | N15: =B15+D15+F15+H15+J15+L15 -> 107058 | O15: =C15+E15+G15+I15+K15+M15 -> 2498924 | P15: =(C15+K15+M15)/(B15+J15+L15) -> 23.341777 | Q15: 12193 | R15: 184394 | S15: =R15/Q15 -> 15.122939 | T15: =(C15+K15+M15+R15)/(B15+J15+L15+Q15) -> 22.50143
A16: 12月 | B16: 33271 | C16: =699829+612 -> 700441 | J16: =15262 -> 15262 | K16: =356234 -> 356234 | L16: 1328 | M16: 29936 | N16: =B16+D16+F16+H16+J16+L16 -> 49861 | O16: =C16+E16+G16+I16+K16+M16 -> 1086611 | P16: =(C16+K16+M16)/(B16+J16+L16) -> 21.792804 | Q16: 11656 | R16: 193940 | S16: =R16/Q16 -> 16.638641 | T16: =(C16+K16+M16+R16)/(B16+J16+L16+Q16) -> 20.816213
A17: 合计 | B17: =SUM(B5:B16) -> 262276 | C17: =SUM(C5:C16) -> 5540629.5 | D17: =SUM(D5:D16) -> 15480 | E17: =SUM(E5:E16) -> 93192.7 | F17: =SUM(F5:F16) -> 7362 | G17: =SUM(G5:G16) -> 60837 | H17: =SUM(H5:H16) -> 21250 | I17: =SUM(I5:I16) -> 246906 | ... O17: =SUM(O5:O16) -> 20245609 | P17: =(C17+K17+M17)/(B17+J17+L17) -> 22.945506 | Q17: =SUM(Q5:Q16) -> 161508 | R17: =SUM(R5:R16) -> 2723718.1 | S17: =R17/Q17 -> 16.864292 | T17: =(C17+K17+M17+R17)/(B17+J17+L17+Q17) -> 21.988575
L19: 11月迪拜运费
L20: 104820.41
K21: 12月 | L21: 迪拜运费 | M21: 26610
Q23: =Q17+N17 -> 1070461

Sheet 25年新历销售
A1: 2025年（新历）昆明统一生物蝴蝶兰销售数量统计
A2: 月份 | C2: 小街基地 | Y2: 斗南门市 | AD2: 两处平均单价（花） | AG2: 砚山基地
B3: 国内数量 | D3: 金额 | F3: 国外 | T3: 小街销售数量合计 | U3: 金额合计 | V3: 小街平均单价（花） | X3: 斗南销售数量 | Z3: 斗南销售金额 | AB3: 斗南平均单价 | AF3: 砚山销售数量 | AH3: 砚山销售金额 | AJ3: 砚山平均单价
B4: 小花 | C4: 大花 | D4: 小 | E4: 大 | F4: 小苗数量 | G4: 金额 | H4: 中苗数量 | I4: 金额 | J4: 大苗数量 | K4: 金额 | L4: 俄罗斯数量 | N4: 金额 | P4: 国外数量 | R4: 国外金额
L5: 小 | M5: 大 | N5: 小 | O5: 大 | P5: 小 | Q5: 大 | R5: 小 | S5: 大 | V5: 小 | W5: 大 | X5: 小 | Y5: 大 | Z5: 小 | AA5: 大 | AB5: 小 | AC5: 大 | AD5: 小花 | AE5: 大花 | AF5: 小 | AG5: 大 | AH5: 小 | AI5: 大 | AJ5: 小 | AK5: 大
